Workbook

Sheet Roster Data
A1: Character | B1: Team | C1: Character Family | D1: Color Variant | E1: Captain | F1: Throwing Arm | G1: Batting Arm | H1: Pitch (1-10) | I1: Bat (1-10) | J1: Field (1-10) | K1: Run (1-10) | L1: Overall Total | M1: Offensive Index | N1: Defensive Index | O1: Athletic Index | P1: P | Q1: C | R1: 1B | S1: 2B | T1: 3B | U1: SS | V1: LF | W1: CF | X1: RF | Y1: Naive Stat-Based Role | Z1: P | AA1: C | AB1: 1B | AC1: 2B | AD1: 3B | AE1: SS | AF1: LF | AG1: CF | AH1: RF | AI1: Optimal Position (Model) | AJ1: Optimal Position Score | AK1: Position Rank | AL1: dist_P_Ryan | AM1: dist_P_Maddux | AN1: dist_C_Bench | AO1: dist_C_Rodriguez | AP1: dist_1B_Pujols | AQ1: dist_1B_Hernandez | AR1: dist_2B_Robinson | AS1: dist_2B_Alomar | AT1: dist_3B_Schmidt | AU1: dist_3B_Brett | AV1: dist_SS_Smith | AW1: dist_SS_Jr. | AX1: dist_LF_Bonds | AY1: dist_LF_Henderson | AZ1: dist_CF_Mays | BA1: dist_CF_Suzuki | BB1: dist_RF_Aaron | BC1: dist_RF_Clemente | BD1: Closest MLB Comp | BE1: Match Score (0-10)
A2: Mario | B2: Mario Fireballs | C2: Mario | D2: No | E2: Yes | F2: Right | G2: Right | H2: 6 | I2: 7 | J2: 6 | K2: 7 | L2: =H2+I2+J2+K2 -> 26 | M2: =ROUND(0.75*I2+0.25*K2,2) -> 7 | N2: =ROUND(0.7*J2+0.3*K2,2) -> 6.3 | O2: =ROUND((H2+J2+K2)/3,2) -> 6.33 | P2: =ROUND(0.85*H2+0.15*J2,2) -> 6 | Q2: =ROUND(0.6*J2+0.3*I2+0.1*H2,2) -> 6.3 | R2: =ROUND(0.7*I2+0.2*J2+0.1*K2,2) -> 6.8 | S2: =ROUND(0.13*I2+0.35*J2+0.52*K2,2) -> 6.65 | T2: =ROUND(0.4*I2+0.5*J2+0.1*K2,2) -> 6.5 | U2: =ROUND(0.1*I2+0.55*J2+0.35*K2,2) -> 6.45 | V2: =ROUND(0.6*I2+0.1*J2+0.3*K2,2) -> 6.9 | W2: =ROUND(0.15*I2+0.3*J2+0.55*K2,2) -> 6.7 | X2: =ROUND(0.46*I2+0.46*J2+0.08*K2,2) -> 6.54 | Y2: =IF(H2=MAX(H2:K2),"Pitcher (arm-first)",IF(I2=MAX(H2:K2),"Bat-first (corner/1B/DH)",IF(J2=MAX(H2:K2),"Defense-first (up-the-middle)","Speed-first (CF/leadoff)"))) -> Bat-first (corner/1B/DH) | Z2: =P2 -> 6 | AA2: =IF(F2="Right",Q2,-1) -> 6.3 | AB2: =R2 -> 6.8 | AC2: =IF(F2="Right",S2,-1) -> 6.65 | AD2: =IF(F2="Right",T2,-1) -> 6.5 | AE2: =IF(F2="Right",U2,-1) -> 6.45 | AF2: =V2 -> 6.9 | AG2: =W2 -> 6.7 | AH2: =X2 -> 6.54 | AI2: =INDEX($Z$1:$AH$1,MATCH(MAX(Z2:AH2),Z2:AH2,0)) -> LF | AJ2: =MAX(Z2:AH2) -> 6.9 | AK2: =SUMPRODUCT(($AI$2:$AI$73=AI2)*($AJ$2:$AJ$73>AJ2))+SUMPRODUCT(($AI$2:$AI$73=AI2)*($AJ$2:$AJ$73=AJ2)*(ROW($AI$2:$AI$73)<ROW(AI2)))+1 -> 1 | AL2: =SQRT((H2-'MLB Archetypes'!$C$2)^2+(I2-'MLB Archetypes'!$D$2)^2+(J2-'MLB Archetypes'!$E$2)^2+(K2-'MLB Archetypes'!$F$2)^2) -> 7.6157731 | AM2: =SQRT((H2-'MLB Archetypes'!$C$3)^2+(I2-'MLB Archetypes'!$D$3)^2+(J2-'MLB Archetypes'!$E$3)^2+(K2-'MLB Archetypes'!$F$3)^2) -> 6.4031242 | AN2: =SQRT((H2-'MLB Archetypes'!$C$4)^2+(I2-'MLB Archetypes'!$D$4)^2+(J2-'MLB Archetypes'!$E$4)^2+(K2-'MLB Archetypes'!$F$4)^2) -> 6.4031242 | AO2: =SQRT((H2-'MLB Archetypes'!$C$5)^2+(I2-'MLB Archetypes'!$D$5)^2+(J2-'MLB Archetypes'!$E$5)^2+(K2-'MLB Archetypes'!$F$5)^2) -> 5.4772256 | AP2: =SQRT((H2-'MLB Archetypes'!$C$6)^2+(I2-'MLB Archetypes'!$D$6)^2+(J2-'MLB Archetypes'!$E$6)^2+(K2-'MLB Archetypes'!$F$6)^2) -> 6 | AQ2: =SQRT((H2-'MLB Archetypes'!$C$7)^2+(I2-'MLB Archetypes'!$D$7)^2+(J2-'MLB Archetypes'!$E$7)^2+(K2-'MLB Archetypes'!$F$7)^2) -> 5.9160798 | AR2: =SQRT((H2-'MLB Archetypes'!$C$8)^2+(I2-'MLB Archetypes'!$D$8)^2+(J2-'MLB Archetypes'!$E$8)^2+(K2-'MLB Archetypes'!$F$8)^2) -> 4.3588989 | AS2: =SQRT((H2-'MLB Archetypes'!$C$9)^2+(I2-'MLB Archetypes'!$D$9)^2+(J2-'MLB Archetypes'!$E$9)^2+(K2-'MLB Archetypes'!$F$9)^2) -> 4.5825757 | AT2: =SQRT((H2-'MLB Archetypes'!$C$10)^2+(I2-'MLB Archetypes'!$D$10)^2+(J2-'MLB Archetypes'!$E$10)^2+(K2-'MLB Archetypes'!$F$10)^2) -> 5.4772256 | AU2: =SQRT((H2-'MLB Archetypes'!$C$11)^2+(I2-'MLB Archetypes'!$D$11)^2+(J2-'MLB Archetypes'!$E$11)^2+(K2-'MLB Archetypes'!$F$11)^2) -> 5.3851648 | AV2: =SQRT((H2-'MLB Archetypes'!$C$12)^2+(I2-'MLB Archetypes'!$D$12)^2+(J2-'MLB Archetypes'!$E$12)^2+(K2-'MLB Archetypes'!$F$12)^2) -> 6.9282032 | AW2: =SQRT((H2-'MLB Archetypes'!$C$13)^2+(I2-'MLB Archetypes'!$D$13)^2+(J2-'MLB Archetypes'!$E$13)^2+(K2-'MLB Archetypes'!$F$13)^2) -> 5.7445626 | AX2: =SQRT((H2-'MLB Archetypes'!$C$14)^2+(I2-'MLB Archetypes'!$D$14)^2+(J2-'MLB Archetypes'!$E$14)^2+(K2-'MLB Archetypes'!$F$14)^2) -> 4.8989795 | AY2: =SQRT((H2-'MLB Archetypes'!$C$15)^2+(I2-'MLB Archetypes'!$D$15)^2+(J2-'MLB Archetypes'!$E$15)^2+(K2-'MLB Archetypes'!$F$15)^2) -> 5.1961524 | AZ2: =SQRT((H2-'MLB Archetypes'!$C$16)^2+(I2-'MLB Archetypes'!$D$16)^2+(J2-'MLB Archetypes'!$E$16)^2+(K2-'MLB Archetypes'!$F$16)^2) -> 5.1961524 | BA2: =SQRT((H2-'MLB Archetypes'!$C$17)^2+(I2-'MLB Archetypes'!$D$17)^2+(J2-'MLB Archetypes'!$E$17)^2+(K2-'MLB Archetypes'!$F$17)^2) -> 4.5825757 | BB2: =SQRT((H2-'MLB Archetypes'!$C$18)^2+(I2-'MLB Archetypes'!$D$18)^2+(J2-'MLB Archetypes'!$E$18)^2+(K2-'MLB Archetypes'!$F$18)^2) -> 4.8989795 | BC2: =SQRT((H2-'MLB Archetypes'!$C$19)^2+(I2-'MLB Archetypes'!$D$19)^2+(J2-'MLB Archetypes'!$E$19)^2+(K2-'MLB Archetypes'!$F$19)^2) -> 4.5825757 | BD2: =INDEX('MLB Archetypes'!$B$2:$B$19,MATCH(MIN(AL2:BC2),AL2:BC2,0)) -> Jackie Robinson | BE2: =ROUND(10-MIN(AL2:BC2)/1.8,1) -> 7.6
A3: Peach | B3: Peach Monarchs | C3: Peach | D3: No | E3: Yes | F3: Right | G3: Right | H3: 9 | I3: 4 | J3: 8 | K3: 5 | L3: =H3+I3+J3+K3 -> 26 | M3: =ROUND(0.75*I3+0.25*K3,2) -> 4.25 | N3: =ROUND(0.7*J3+0.3*K3,2) -> 7.1 | O3: =ROUND((H3+J3+K3)/3,2) -> 7.33 | P3: =ROUND(0.85*H3+0.15*J3,2) -> 8.85 | Q3: =ROUND(0.6*J3+0.3*I3+0.1*H3,2) -> 6.9 | R3: =ROUND(0.7*I3+0.2*J3+0.1*K3,2) -> 4.9 | S3: =ROUND(0.13*I3+0.35*J3+0.52*K3,2) -> 5.92 | T3: =ROUND(0.4*I3+0.5*J3+0.1*K3,2) -> 6.1 | U3: =ROUND(0.1*I3+0.55*J3+0.35*K3,2) -> 6.55 | V3: =ROUND(0.6*I3+0.1*J3+0.3*K3,2) -> 4.7 | W3: =ROUND(0.15*I3+0.3*J3+0.55*K3,2) -> 5.75 | X3: =ROUND(0.46*I3+0.46*J3+0.08*K3,2) -> 5.92 | Y3: =IF(H3=MAX(H3:K3),"Pitcher (arm-first)",IF(I3=MAX(H3:K3),"Bat-first (corner/1B/DH)",IF(J3=MAX(H3:K3),"Defense-first (up-the-middle)","Speed-first (CF/leadoff)"))) -> Pitcher (arm-first) | Z3: =P3 -> 8.85 | AA3: =IF(F3="Right",Q3,-1) -> 6.9 | AB3: =R3 -> 4.9 | AC3: =IF(F3="Right",S3,-1) -> 5.92 | AD3: =IF(F3="Right",T3,-1) -> 6.1 | AE3: =IF(F3="Right",U3,-1) -> 6.55 | AF3: =V3 -> 4.7 | AG3: =W3 -> 5.75 | AH3: =X3 -> 5.92 | AI3: =INDEX($Z$1:$AH$1,MATCH(MAX(Z3:AH3),Z3:AH3,0)) -> P | AJ3: =MAX(Z3:AH3) -> 8.85 | AK3: =SUMPRODUCT(($AI$2:$AI$73=AI3)*($AJ$2:$AJ$73>AJ3))+SUMPRODUCT(($AI$2:$AI$73=AI3)*($AJ$2:$AJ$73=AJ3)*(ROW($AI$2:$AI$73)<ROW(AI3)))+1 -> 1 | AL3: =SQRT((H3-'MLB Archetypes'!$C$2)^2+(I3-'MLB Archetypes'!$D$2)^2+(J3-'MLB Archetypes'!$E$2)^2+(K3-'MLB Archetypes'!$F$2)^2) -> 4.2426407 | AM3: =SQRT((H3-'MLB Archetypes'!$C$3)^2+(I3-'MLB Archetypes'!$D$3)^2+(J3-'MLB Archetypes'!$E$3)^2+(K3-'MLB Archetypes'!$F$3)^2) -> 3 | AN3: =SQRT((H3-'MLB Archetypes'!$C$4)^2+(I3-'MLB Archetypes'!$D$4)^2+(J3-'MLB Archetypes'!$E$4)^2+(K3-'MLB Archetypes'!$F$4)^2) -> 7.9372539 | AO3: =SQRT((H3-'MLB Archetypes'!$C$5)^2+(I3-'MLB Archetypes'!$D$5)^2+(J3-'MLB Archetypes'!$E$5)^2+(K3-'MLB Archetypes'!$F$5)^2) -> 7.3484692 | AP3: =SQRT((H3-'MLB Archetypes'!$C$6)^2+(I3-'MLB Archetypes'!$D$6)^2+(J3-'MLB Archetypes'!$E$6)^2+(K3-'MLB Archetypes'!$F$6)^2) -> 9.0553851 | AQ3: =SQRT((H3-'MLB Archetypes'!$C$7)^2+(I3-'MLB Archetypes'!$D$7)^2+(J3-'MLB Archetypes'!$E$7)^2+(K3-'MLB Archetypes'!$F$7)^2) -> 7.4161985 | AR3: =SQRT((H3-'MLB Archetypes'!$C$8)^2+(I3-'MLB Archetypes'!$D$8)^2+(J3-'MLB Archetypes'!$E$8)^2+(K3-'MLB Archetypes'!$F$8)^2) -> 7.9372539 | AS3: =SQRT((H3-'MLB Archetypes'!$C$9)^2+(I3-'MLB Archetypes'!$D$9)^2+(J3-'MLB Archetypes'!$E$9)^2+(K3-'MLB Archetypes'!$F$9)^2) -> 7.6811457 | AT3: =SQRT((H3-'MLB Archetypes'!$C$10)^2+(I3-'MLB Archetypes'!$D$10)^2+(J3-'MLB Archetypes'!$E$10)^2+(K3-'MLB Archetypes'!$F$10)^2) -> 8.1240384 | AU3: =SQRT((H3-'MLB Archetypes'!$C$11)^2+(I3-'MLB Archetypes'!$D$11)^2+(J3-'MLB Archetypes'!$E$11)^2+(K3-'MLB Archetypes'!$F$11)^2) -> 8.8881944 | AV3: =SQRT((H3-'MLB Archetypes'!$C$12)^2+(I3-'MLB Archetypes'!$D$12)^2+(J3-'MLB Archetypes'!$E$12)^2+(K3-'MLB Archetypes'!$F$12)^2) -> 7.6157731 | AW3: =SQRT((H3-'MLB Archetypes'!$C$13)^2+(I3-'MLB Archetypes'!$D$13)^2+(J3-'MLB Archetypes'!$E$13)^2+(K3-'MLB Archetypes'!$F$13)^2) -> 7.9372539 | AX3: =SQRT((H3-'MLB Archetypes'!$C$14)^2+(I3-'MLB Archetypes'!$D$14)^2+(J3-'MLB Archetypes'!$E$14)^2+(K3-'MLB Archetypes'!$F$14)^2) -> 8.8317609 | AY3: =SQRT((H3-'MLB Archetypes'!$C$15)^2+(I3-'MLB Archetypes'!$D$15)^2+(J3-'MLB Archetypes'!$E$15)^2+(K3-'MLB Archetypes'!$F$15)^2) -> 9.3273791 | AZ3: =SQRT((H3-'MLB Archetypes'!$C$16)^2+(I3-'MLB Archetypes'!$D$16)^2+(J3-'MLB Archetypes'!$E$16)^2+(K3-'MLB Archetypes'!$F$16)^2) -> 8.660254 | BA3: =SQRT((H3-'MLB Archetypes'!$C$17)^2+(I3-'MLB Archetypes'!$D$17)^2+(J3-'MLB Archetypes'!$E$17)^2+(K3-'MLB Archetypes'!$F$17)^2) -> 8.660254 | BB3: =SQRT((H3-'MLB Archetypes'!$C$18)^2+(I3-'MLB Archetypes'!$D$18)^2+(J3-'MLB Archetypes'!$E$18)^2+(K3-'MLB Archetypes'!$F$18)^2) -> 8.8317609 | BC3: =SQRT((H3-'MLB Archetypes'!$C$19)^2+(I3-'MLB Archetypes'!$D$19)^2+(J3-'MLB Archetypes'!$E$19)^2+(K3-'MLB Archetypes'!$F$19)^2) -> 7.6811457 | BD3: =INDEX('MLB Archetypes'!$B$2:$B$19,MATCH(MIN(AL3:BC3),AL3:BC3,0)) -> Greg Maddux | BE3: =ROUND(10-MIN(AL3:BC3)/1.8,1) -> 8.3
A4: Yoshi | B4: Yoshi Eggs | C4: Yoshi | D4: No | E4: Yes | F4: Right | G4: Left | H4: 4 | I4: 4 | J4: 6 | K4: 9 | L4: =H4+I4+J4+K4 -> 23 | M4: =ROUND(0.75*I4+0.25*K4,2) -> 5.25 | N4: =ROUND(0.7*J4+0.3*K4,2) -> 6.9 | O4: =ROUND((H4+J4+K4)/3,2) -> 6.33 | P4: =ROUND(0.85*H4+0.15*J4,2) -> 4.3 | Q4: =ROUND(0.6*J4+0.3*I4+0.1*H4,2) -> 5.2 | R4: =ROUND(0.7*I4+0.2*J4+0.1*K4,2) -> 4.9 | S4: =ROUND(0.13*I4+0.35*J4+0.52*K4,2) -> 7.3 | T4: =ROUND(0.4*I4+0.5*J4+0.1*K4,2) -> 5.5 | U4: =ROUND(0.1*I4+0.55*J4+0.35*K4,2) -> 6.85 | V4: =ROUND(0.6*I4+0.1*J4+0.3*K4,2) -> 5.7 | W4: =ROUND(0.15*I4+0.3*J4+0.55*K4,2) -> 7.35 | X4: =ROUND(0.46*I4+0.46*J4+0.08*K4,2) -> 5.32 | Y4: =IF(H4=MAX(H4:K4),"Pitcher (arm-first)",IF(I4=MAX(H4:K4),"Bat-first (corner/1B/DH)",IF(J4=MAX(H4:K4),"Defense-first (up-the-middle)","Speed-first (CF/leadoff)"))) -> Speed-first (CF/leadoff) | Z4: =P4 -> 4.3 | AA4: =IF(F4="Right",Q4,-1) -> 5.2 | AB4: =R4 -> 4.9 | AC4: =IF(F4="Right",S4,-1) -> 7.3 | AD4: =IF(F4="Right",T4,-1) -> 5.5 | AE4: =IF(F4="Right",U4,-1) -> 6.85 | AF4: =V4 -> 5.7 | AG4: =W4 -> 7.35 | AH4: =X4 -> 5.32 | AI4: =INDEX($Z$1:$AH$1,MATCH(MAX(Z4:AH4),Z4:AH4,0)) -> CF | AJ4: =MAX(Z4:AH4) -> 7.35 | AK4: =SUMPRODUCT(($AI$2:$AI$73=AI4)*($AJ$2:$AJ$73>AJ4))+SUMPRODUCT(($AI$2:$AI$73=AI4)*($AJ$2:$AJ$73=AJ4)*(ROW($AI$2:$AI$73)<ROW(AI4)))+1 -> 1 | AL4: =SQRT((H4-'MLB Archetypes'!$C$2)^2+(I4-'MLB Archetypes'!$D$2)^2+(J4-'MLB Archetypes'!$E$2)^2+(K4-'MLB Archetypes'!$F$2)^2) -> 8.7749644 | AM4: =SQRT((H4-'MLB Archetypes'!$C$3)^2+(I4-'MLB Archetypes'!$D$3)^2+(J4-'MLB Archetypes'!$E$3)^2+(K4-'MLB Archetypes'!$F$3)^2) -> 7.8740079 | AN4: =SQRT((H4-'MLB Archetypes'!$C$4)^2+(I4-'MLB Archetypes'!$D$4)^2+(J4-'MLB Archetypes'!$E$4)^2+(K4-'MLB Archetypes'!$F$4)^2) -> 7.6157731 | AO4: =SQRT((H4-'MLB Archetypes'!$C$5)^2+(I4-'MLB Archetypes'!$D$5)^2+(J4-'MLB Archetypes'!$E$5)^2+(K4-'MLB Archetypes'!$F$5)^2) -> 6.0827625 | AP4: =SQRT((H4-'MLB Archetypes'!$C$6)^2+(I4-'MLB Archetypes'!$D$6)^2+(J4-'MLB Archetypes'!$E$6)^2+(K4-'MLB Archetypes'!$F$6)^2) -> 8.0622577 | AQ4: =SQRT((H4-'MLB Archetypes'!$C$7)^2+(I4-'MLB Archetypes'!$D$7)^2+(J4-'MLB Archetypes'!$E$7)^2+(K4-'MLB Archetypes'!$F$7)^2) -> 6.4807407 | AR4: =SQRT((H4-'MLB Archetypes'!$C$8)^2+(I4-'MLB Archetypes'!$D$8)^2+(J4-'MLB Archetypes'!$E$8)^2+(K4-'MLB Archetypes'!$F$8)^2) -> 3.1622777 | AS4: =SQRT((H4-'MLB Archetypes'!$C$9)^2+(I4-'MLB Archetypes'!$D$9)^2+(J4-'MLB Archetypes'!$E$9)^2+(K4-'MLB Archetypes'!$F$9)^2) -> 5.0990195 | AT4: =SQRT((H4-'MLB Archetypes'!$C$10)^2+(I4-'MLB Archetypes'!$D$10)^2+(J4-'MLB Archetypes'!$E$10)^2+(K4-'MLB Archetypes'!$F$10)^2) -> 7 | AU4: =SQRT((H4-'MLB Archetypes'!$C$11)^2+(I4-'MLB Archetypes'!$D$11)^2+(J4-'MLB Archetypes'!$E$11)^2+(K4-'MLB Archetypes'!$F$11)^2) -> 7.3484692 | AV4: =SQRT((H4-'MLB Archetypes'!$C$12)^2+(I4-'MLB Archetypes'!$D$12)^2+(J4-'MLB Archetypes'!$E$12)^2+(K4-'MLB Archetypes'!$F$12)^2) -> 5 | AW4: =SQRT((H4-'MLB Archetypes'!$C$13)^2+(I4-'MLB Archetypes'!$D$13)^2+(J4-'MLB Archetypes'!$E$13)^2+(K4-'MLB Archetypes'!$F$13)^2) -> 7.0710678 | AX4: =SQRT((H4-'MLB Archetypes'!$C$14)^2+(I4-'MLB Archetypes'!$D$14)^2+(J4-'MLB Archetypes'!$E$14)^2+(K4-'MLB Archetypes'!$F$14)^2) -> 6.7082039 | AY4: =SQRT((H4-'MLB Archetypes'!$C$15)^2+(I4-'MLB Archetypes'!$D$15)^2+(J4-'MLB Archetypes'!$E$15)^2+(K4-'MLB Archetypes'!$F$15)^2) -> 3.1622777 | AZ4: =SQRT((H4-'MLB Archetypes'!$C$16)^2+(I4-'MLB Archetypes'!$D$16)^2+(J4-'MLB Archetypes'!$E$16)^2+(K4-'MLB Archetypes'!$F$16)^2) -> 5.4772256 | BA4: =SQRT((H4-'MLB Archetypes'!$C$17)^2+(I4-'MLB Archetypes'!$D$17)^2+(J4-'MLB Archetypes'!$E$17)^2+(K4-'MLB Archetypes'!$F$17)^2) -> 3.7416574 | BB4: =SQRT((H4-'MLB Archetypes'!$C$18)^2+(I4-'MLB Archetypes'!$D$18)^2+(J4-'MLB Archetypes'!$E$18)^2+(K4-'MLB Archetypes'!$F$18)^2) -> 6.7082039 | BC4: =SQRT((H4-'MLB Archetypes'!$C$19)^2+(I4-'MLB Archetypes'!$D$19)^2+(J4-'MLB Archetypes'!$E$19)^2+(K4-'MLB Archetypes'!$F$19)^2) -> 5.0990195 | BD4: =INDEX('MLB Archetypes'!$B$2:$B$19,MATCH(MIN(AL4:BC4),AL4:BC4,0)) -> Jackie Robinson | BE4: =ROUND(10-MIN(AL4:BC4)/1.8,1) -> 8.2
A5: Wario | B5: Wario Muscles | C5: Wario | D5: No | E5: Yes | F5: Right | G5: Right | H5: 5 | I5: 8 | J5: 3 | K5: 4 | L5: =H5+I5+J5+K5 -> 20 | M5: =ROUND(0.75*I5+0.25*K5,2) -> 7 | N5: =ROUND(0.7*J5+0.3*K5,2) -> 3.3 | O5: =ROUND((H5+J5+K5)/3,2) -> 4 | P5: =ROUND(0.85*H5+0.15*J5,2) -> 4.7 | Q5: =ROUND(0.6*J5+0.3*I5+0.1*H5,2) -> 4.7 | R5: =ROUND(0.7*I5+0.2*J5+0.1*K5,2) -> 6.6 | S5: =ROUND(0.13*I5+0.35*J5+0.52*K5,2) -> 4.17 | T5: =ROUND(0.4*I5+0.5*J5+0.1*K5,2) -> 5.1 | U5: =ROUND(0.1*I5+0.55*J5+0.35*K5,2) -> 3.85 | V5: =ROUND(0.6*I5+0.1*J5+0.3*K5,2) -> 6.3 | W5: =ROUND(0.15*I5+0.3*J5+0.55*K5,2) -> 4.3 | X5: =ROUND(0.46*I5+0.46*J5+0.08*K5,2) -> 5.38 | Y5: =IF(H5=MAX(H5:K5),"Pitcher (arm-first)",IF(I5=MAX(H5:K5),"Bat-first (corner/1B/DH)",IF(J5=MAX(H5:K5),"Defense-first (up-the-middle)","Speed-first (CF/leadoff)"))) -> Bat-first (corner/1B/DH) | Z5: =P5 -> 4.7 | AA5: =IF(F5="Right",Q5,-1) -> 4.7 | AB5: =R5 -> 6.6 | AC5: =IF(F5="Right",S5,-1) -> 4.17 | AD5: =IF(F5="Right",T5,-1) -> 5.1 | AE5: =IF(F5="Right",U5,-1) -> 3.85 | AF5: =V5 -> 6.3 | AG5: =W5 -> 4.3 | AH5: =X5 -> 5.38 | AI5: =INDEX($Z$1:$AH$1,MATCH(MAX(Z5:AH5),Z5:AH5,0)) -> 1B | AJ5: =MAX(Z5:AH5) -> 6.6 | AK5: =SUMPRODUCT(($AI$2:$AI$73=AI5)*($AJ$2:$AJ$73>AJ5))+SUMPRODUCT(($AI$2:$AI$73=AI5)*($AJ$2:$AJ$73=AJ5)*(ROW($AI$2:$AI$73)<ROW(AI5)))+1 -> 9 | AL5: =SQRT((H5-'MLB Archetypes'!$C$2)^2+(I5-'MLB Archetypes'!$D$2)^2+(J5-'MLB Archetypes'!$E$2)^2+(K5-'MLB Archetypes'!$F$2)^2) -> 8.1240384 | AM5: =SQRT((H5-'MLB Archetypes'!$C$3)^2+(I5-'MLB Archetypes'!$D$3)^2+(J5-'MLB Archetypes'!$E$3)^2+(K5-'MLB Archetypes'!$F$3)^2) -> 7.1414284 | AN5: =SQRT((H5-'MLB Archetypes'!$C$4)^2+(I5-'MLB Archetypes'!$D$4)^2+(J5-'MLB Archetypes'!$E$4)^2+(K5-'MLB Archetypes'!$F$4)^2) -> 6.8556546 | AO5: =SQRT((H5-'MLB Archetypes'!$C$5)^2+(I5-'MLB Archetypes'!$D$5)^2+(J5-'MLB Archetypes'!$E$5)^2+(K5-'MLB Archetypes'!$F$5)^2) -> 6.164414 | AP5: =SQRT((H5-'MLB Archetypes'!$C$6)^2+(I5-'MLB Archetypes'!$D$6)^2+(J5-'MLB Archetypes'!$E$6)^2+(K5-'MLB Archetypes'!$F$6)^2) -> 4.472136 | AQ5: =SQRT((H5-'MLB Archetypes'!$C$7)^2+(I5-'MLB Archetypes'!$D$7)^2+(J5-'MLB Archetypes'!$E$7)^2+(K5-'MLB Archetypes'!$F$7)^2) -> 7 | AR5: =SQRT((H5-'MLB Archetypes'!$C$8)^2+(I5-'MLB Archetypes'!$D$8)^2+(J5-'MLB Archetypes'!$E$8)^2+(K5-'MLB Archetypes'!$F$8)^2) -> 6.7082039 | AS5: =SQRT((H5-'MLB Archetypes'!$C$9)^2+(I5-'MLB Archetypes'!$D$9)^2+(J5-'MLB Archetypes'!$E$9)^2+(K5-'MLB Archetypes'!$F$9)^2) -> 6.244998 | AT5: =SQRT((H5-'MLB Archetypes'!$C$10)^2+(I5-'MLB Archetypes'!$D$10)^2+(J5-'MLB Archetypes'!$E$10)^2+(K5-'MLB Archetypes'!$F$10)^2) -> 5.8309519 | AU5: =SQRT((H5-'MLB Archetypes'!$C$11)^2+(I5-'MLB Archetypes'!$D$11)^2+(J5-'MLB Archetypes'!$E$11)^2+(K5-'MLB Archetypes'!$F$11)^2) -> 4.3588989 | AV5: =SQRT((H5-'MLB Archetypes'!$C$12)^2+(I5-'MLB Archetypes'!$D$12)^2+(J5-'MLB Archetypes'!$E$12)^2+(K5-'MLB Archetypes'!$F$12)^2) -> 9.591663 | AW5: =SQRT((H5-'MLB Archetypes'!$C$13)^2+(I5-'MLB Archetypes'!$D$13)^2+(J5-'MLB Archetypes'!$E$13)^2+(K5-'MLB Archetypes'!$F$13)^2) -> 5.1961524 | AX5: =SQRT((H5-'MLB Archetypes'!$C$14)^2+(I5-'MLB Archetypes'!$D$14)^2+(J5-'MLB Archetypes'!$E$14)^2+(K5-'MLB Archetypes'!$F$14)^2) -> 4.472136 | AY5: =SQRT((H5-'MLB Archetypes'!$C$15)^2+(I5-'MLB Archetypes'!$D$15)^2+(J5-'MLB Archetypes'!$E$15)^2+(K5-'MLB Archetypes'!$F$15)^2) -> 7.2801099 | AZ5: =SQRT((H5-'MLB Archetypes'!$C$16)^2+(I5-'MLB Archetypes'!$D$16)^2+(J5-'MLB Archetypes'!$E$16)^2+(K5-'MLB Archetypes'!$F$16)^2) -> 7.8102497 | BA5: =SQRT((H5-'MLB Archetypes'!$C$17)^2+(I5-'MLB Archetypes'!$D$17)^2+(J5-'MLB Archetypes'!$E$17)^2+(K5-'MLB Archetypes'!$F$17)^2) -> 7.1414284 | BB5: =SQRT((H5-'MLB Archetypes'!$C$18)^2+(I5-'MLB Archetypes'!$D$18)^2+(J5-'MLB Archetypes'!$E$18)^2+(K5-'MLB Archetypes'!$F$18)^2) -> 4.472136 | BC5: =SQRT((H5-'MLB Archetypes'!$C$19)^2+(I5-'MLB Archetypes'!$D$19)^2+(J5-'MLB Archetypes'!$E$19)^2+(K5-'MLB Archetypes'!$F$19)^2) -> 6.244998 | BD5: =INDEX('MLB Archetypes'!$B$2:$B$19,MATCH(MIN(AL5:BC5),AL5:BC5,0)) -> George Brett | BE5: =ROUND(10-MIN(AL5:BC5)/1.8,1) -> 7.6
A6: Donkey Kong | B6: DK Wilds | C6: Donkey Kong | D6: No | E6: Yes | F6: Right | G6: Left | H6: 6 | I6: 9 | J6: 3 | K6: 2 | L6: =H6+I6+J6+K6 -> 20 | M6: =ROUND(0.75*I6+0.25*K6,2) -> 7.25 | N6: =ROUND(0.7*J6+0.3*K6,2) -> 2.7 | O6: =ROUND((H6+J6+K6)/3,2) -> 3.67 | P6: =ROUND(0.85*H6+0.15*J6,2) -> 5.55 | Q6: =ROUND(0.6*J6+0.3*I6+0.1*H6,2) -> 5.1 | R6: =ROUND(0.7*I6+0.2*J6+0.1*K6,2) -> 7.1 | S6: =ROUND(0.13*I6+0.35*J6+0.52*K6,2) -> 3.26 | T6: =ROUND(0.4*I6+0.5*J6+0.1*K6,2) -> 5.3 | U6: =ROUND(0.1*I6+0.55*J6+0.35*K6,2) -> 3.25 | V6: =ROUND(0.6*I6+0.1*J6+0.3*K6,2) -> 6.3 | W6: =ROUND(0.15*I6+0.3*J6+0.55*K6,2) -> 3.35 | X6: =ROUND(0.46*I6+0.46*J6+0.08*K6,2) -> 5.68 | Y6: =IF(H6=MAX(H6:K6),"Pitcher (arm-first)",IF(I6=MAX(H6:K6),"Bat-first (corner/1B/DH)",IF(J6=MAX(H6:K6),"Defense-first (up-the-middle)","Speed-first (CF/leadoff)"))) -> Bat-first (corner/1B/DH) | Z6: =P6 -> 5.55 | AA6: =IF(F6="Right",Q6,-1) -> 5.1 | AB6: =R6 -> 7.1 | AC6: =IF(F6="Right",S6,-1) -> 3.26 | AD6: =IF(F6="Right",T6,-1) -> 5.3 | AE6: =IF(F6="Right",U6,-1) -> 3.25 | AF6: =V6 -> 6.3 | AG6: =W6 -> 3.35 | AH6: =X6 -> 5.68 | AI6: =INDEX($Z$1:$AH$1,MATCH(MAX(Z6:AH6),Z6:AH6,0)) -> 1B | AJ6: =MAX(Z6:AH6) -> 7.1 | AK6: =SUMPRODUCT(($AI$2:$AI$73=AI6)*($AJ$2:$AJ$73>AJ6))+SUMPRODUCT(($AI$2:$AI$73=AI6)*($AJ$2:$AJ$73=AJ6)*(ROW($AI$2:$AI$73)<ROW(AI6)))+1 -> 6 | AL6: =SQRT((H6-'MLB Archetypes'!$C$2)^2+(I6-'MLB Archetypes'!$D$2)^2+(J6-'MLB Archetypes'!$E$2)^2+(K6-'MLB Archetypes'!$F$2)^2) -> 8.3666003 | AM6: =SQRT((H6-'MLB Archetypes'!$C$3)^2+(I6-'MLB Archetypes'!$D$3)^2+(J6-'MLB Archetypes'!$E$3)^2+(K6-'MLB Archetypes'!$F$3)^2) -> 7.4161985 | AN6: =SQRT((H6-'MLB Archetypes'!$C$4)^2+(I6-'MLB Archetypes'!$D$4)^2+(J6-'MLB Archetypes'!$E$4)^2+(K6-'MLB Archetypes'!$F$4)^2) -> 7.5498344 | AO6: =SQRT((H6-'MLB Archetypes'!$C$5)^2+(I6-'MLB Archetypes'!$D$5)^2+(J6-'MLB Archetypes'!$E$5)^2+(K6-'MLB Archetypes'!$F$5)^2) -> 7.3484692 | AP6: =SQRT((H6-'MLB Archetypes'!$C$6)^2+(I6-'MLB Archetypes'!$D$6)^2+(J6-'MLB Archetypes'!$E$6)^2+(K6-'MLB Archetypes'!$F$6)^2) -> 5.0990195 | AQ6: =SQRT((H6-'MLB Archetypes'!$C$7)^2+(I6-'MLB Archetypes'!$D$7)^2+(J6-'MLB Archetypes'!$E$7)^2+(K6-'MLB Archetypes'!$F$7)^2) -> 8.0622577 | AR6: =SQRT((H6-'MLB Archetypes'!$C$8)^2+(I6-'MLB Archetypes'!$D$8)^2+(J6-'MLB Archetypes'!$E$8)^2+(K6-'MLB Archetypes'!$F$8)^2) -> 8.7749644 | AS6: =SQRT((H6-'MLB Archetypes'!$C$9)^2+(I6-'MLB Archetypes'!$D$9)^2+(J6-'MLB Archetypes'!$E$9)^2+(K6-'MLB Archetypes'!$F$9)^2) -> 7.8102497 | AT6: =SQRT((H6-'MLB Archetypes'!$C$10)^2+(I6-'MLB Archetypes'!$D$10)^2+(J6-'MLB Archetypes'!$E$10)^2+(K6-'MLB Archetypes'!$F$10)^2) -> 6.78233 | AU6: =SQRT((H6-'MLB Archetypes'!$C$11)^2+(I6-'MLB Archetypes'!$D$11)^2+(J6-'MLB Archetypes'!$E$11)^2+(K6-'MLB Archetypes'!$F$11)^2) -> 5.3851648 | AV6: =SQRT((H6-'MLB Archetypes'!$C$12)^2+(I6-'MLB Archetypes'!$D$12)^2+(J6-'MLB Archetypes'!$E$12)^2+(K6-'MLB Archetypes'!$F$12)^2) -> 11.224972 | AW6: =SQRT((H6-'MLB Archetypes'!$C$13)^2+(I6-'MLB Archetypes'!$D$13)^2+(J6-'MLB Archetypes'!$E$13)^2+(K6-'MLB Archetypes'!$F$13)^2) -> 6.0827625 | AX6: =SQRT((H6-'MLB Archetypes'!$C$14)^2+(I6-'MLB Archetypes'!$D$14)^2+(J6-'MLB Archetypes'!$E$14)^2+(K6-'MLB Archetypes'!$F$14)^2) -> 5.8309519 | AY6: =SQRT((H6-'MLB Archetypes'!$C$15)^2+(I6-'MLB Archetypes'!$D$15)^2+(J6-'MLB Archetypes'!$E$15)^2+(K6-'MLB Archetypes'!$F$15)^2) -> 9.6436508 | AZ6: =SQRT((H6-'MLB Archetypes'!$C$16)^2+(I6-'MLB Archetypes'!$D$16)^2+(J6-'MLB Archetypes'!$E$16)^2+(K6-'MLB Archetypes'!$F$16)^2) -> 9.4339811 | BA6: =SQRT((H6-'MLB Archetypes'!$C$17)^2+(I6-'MLB Archetypes'!$D$17)^2+(J6-'MLB Archetypes'!$E$17)^2+(K6-'MLB Archetypes'!$F$17)^2) -> 9.2195445 | BB6: =SQRT((H6-'MLB Archetypes'!$C$18)^2+(I6-'MLB Archetypes'!$D$18)^2+(J6-'MLB Archetypes'!$E$18)^2+(K6-'MLB Archetypes'!$F$18)^2) -> 5.8309519 | BC6: =SQRT((H6-'MLB Archetypes'!$C$19)^2+(I6-'MLB Archetypes'!$D$19)^2+(J6-'MLB Archetypes'!$E$19)^2+(K6-'MLB Archetypes'!$F$19)^2) -> 7.8102497 | BD6: =INDEX('MLB Archetypes'!$B$2:$B$19,MATCH(MIN(AL6:BC6),AL6:BC6,0)) -> Albert Pujols | BE6: =ROUND(10-MIN(AL6:BC6)/1.8,1) -> 7.2
A7: Bowser | B7: Bowser Monsters | C7: Bowser | D7: No | E7: Yes | F7: Right | G7: Left | H7: 5 | I7: 10 | J7: 3 | K7: 3 | L7: =H7+I7+J7+K7 -> 21 | M7: =ROUND(0.75*I7+0.25*K7,2) -> 8.25 | N7: =ROUND(0.7*J7+0.3*K7,2) -> 3 | O7: =ROUND((H7+J7+K7)/3,2) -> 3.67 | P7: =ROUND(0.85*H7+0.15*J7,2) -> 4.7 | Q7: =ROUND(0.6*J7+0.3*I7+0.1*H7,2) -> 5.3 | R7: =ROUND(0.7*I7+0.2*J7+0.1*K7,2) -> 7.9 | S7: =ROUND(0.13*I7+0.35*J7+0.52*K7,2) -> 3.91 | T7: =ROUND(0.4*I7+0.5*J7+0.1*K7,2) -> 5.8 | U7: =ROUND(0.1*I7+0.55*J7+0.35*K7,2) -> 3.7 | V7: =ROUND(0.6*I7+0.1*J7+0.3*K7,2) -> 7.2 | W7: =ROUND(0.15*I7+0.3*J7+0.55*K7,2) -> 4.05 | X7: =ROUND(0.46*I7+0.46*J7+0.08*K7,2) -> 6.22 | Y7: =IF(H7=MAX(H7:K7),"Pitcher (arm-first)",IF(I7=MAX(H7:K7),"Bat-first (corner/1B/DH)",IF(J7=MAX(H7:K7),"Defense-first (up-the-middle)","Speed-first (CF/leadoff)"))) -> Bat-first (corner/1B/DH) | Z7: =P7 -> 4.7 | AA7: =IF(F7="Right",Q7,-1) -> 5.3 | AB7: =R7 -> 7.9 | AC7: =IF(F7="Right",S7,-1) -> 3.91 | AD7: =IF(F7="Right",T7,-1) -> 5.8 | AE7: =IF(F7="Right",U7,-1) -> 3.7 | AF7: =V7 -> 7.2 | AG7: =W7 -> 4.05 | AH7: =X7 -> 6.22 | AI7: =INDEX($Z$1:$AH$1,MATCH(MAX(Z7:AH7),Z7:AH7,0)) -> 1B | AJ7: =MAX(Z7:AH7) -> 7.9 | AK7: =SUMPRODUCT(($AI$2:$AI$73=AI7)*($AJ$2:$AJ$73>AJ7))+SUMPRODUCT(($AI$2:$AI$73=AI7)*($AJ$2:$AJ$73=AJ7)*(ROW($AI$2:$AI$73)<ROW(AI7)))+1 -> 2 | AL7: =SQRT((H7-'MLB Archetypes'!$C$2)^2+(I7-'MLB Archetypes'!$D$2)^2+(J7-'MLB Archetypes'!$E$2)^2+(K7-'MLB Archetypes'!$F$2)^2) -> 9.6436508 | AM7: =SQRT((H7-'MLB Archetypes'!$C$3)^2+(I7-'MLB Archetypes'!$D$3)^2+(J7-'MLB Archetypes'!$E$3)^2+(K7-'MLB Archetypes'!$F$3)^2) -> 8.6023253 | AN7: =SQRT((H7-'MLB Archetypes'!$C$4)^2+(I7-'MLB Archetypes'!$D$4)^2+(J7-'MLB Archetypes'!$E$4)^2+(K7-'MLB Archetypes'!$F$4)^2) -> 7.3484692 | AO7: =SQRT((H7-'MLB Archetypes'!$C$5)^2+(I7-'MLB Archetypes'!$D$5)^2+(J7-'MLB Archetypes'!$E$5)^2+(K7-'MLB Archetypes'!$F$5)^2) -> 7.1414284 | AP7: =SQRT((H7-'MLB Archetypes'!$C$6)^2+(I7-'MLB Archetypes'!$D$6)^2+(J7-'MLB Archetypes'!$E$6)^2+(K7-'MLB Archetypes'!$F$6)^2) -> 4.3588989 | AQ7: =SQRT((H7-'MLB Archetypes'!$C$7)^2+(I7-'MLB Archetypes'!$D$7)^2+(J7-'MLB Archetypes'!$E$7)^2+(K7-'MLB Archetypes'!$F$7)^2) -> 7.8740079 | AR7: =SQRT((H7-'MLB Archetypes'!$C$8)^2+(I7-'MLB Archetypes'!$D$8)^2+(J7-'MLB Archetypes'!$E$8)^2+(K7-'MLB Archetypes'!$F$8)^2) -> 8.1240384 | AS7: =SQRT((H7-'MLB Archetypes'!$C$9)^2+(I7-'MLB Archetypes'!$D$9)^2+(J7-'MLB Archetypes'!$E$9)^2+(K7-'MLB Archetypes'!$F$9)^2) -> 7.2111026 | AT7: =SQRT((H7-'MLB Archetypes'!$C$10)^2+(I7-'MLB Archetypes'!$D$10)^2+(J7-'MLB Archetypes'!$E$10)^2+(K7-'MLB Archetypes'!$F$10)^2) -> 6.244998 | AU7: =SQRT((H7-'MLB Archetypes'!$C$11)^2+(I7-'MLB Archetypes'!$D$11)^2+(J7-'MLB Archetypes'!$E$11)^2+(K7-'MLB Archetypes'!$F$11)^2) -> 4.472136 | AV7: =SQRT((H7-'MLB Archetypes'!$C$12)^2+(I7-'MLB Archetypes'!$D$12)^2+(J7-'MLB Archetypes'!$E$12)^2+(K7-'MLB Archetypes'!$F$12)^2) -> 11.090537 | AW7: =SQRT((H7-'MLB Archetypes'!$C$13)^2+(I7-'MLB Archetypes'!$D$13)^2+(J7-'MLB Archetypes'!$E$13)^2+(K7-'MLB Archetypes'!$F$13)^2) -> 5.8309519 | AX7: =SQRT((H7-'MLB Archetypes'!$C$14)^2+(I7-'MLB Archetypes'!$D$14)^2+(J7-'MLB Archetypes'!$E$14)^2+(K7-'MLB Archetypes'!$F$14)^2) -> 4.7958315 | AY7: =SQRT((H7-'MLB Archetypes'!$C$15)^2+(I7-'MLB Archetypes'!$D$15)^2+(J7-'MLB Archetypes'!$E$15)^2+(K7-'MLB Archetypes'!$F$15)^2) -> 8.8317609 | AZ7: =SQRT((H7-'MLB Archetypes'!$C$16)^2+(I7-'MLB Archetypes'!$D$16)^2+(J7-'MLB Archetypes'!$E$16)^2+(K7-'MLB Archetypes'!$F$16)^2) -> 8.6023253 | BA7: =SQRT((H7-'MLB Archetypes'!$C$17)^2+(I7-'MLB Archetypes'!$D$17)^2+(J7-'MLB Archetypes'!$E$17)^2+(K7-'MLB Archetypes'!$F$17)^2) -> 8.3666003 | BB7: =SQRT((H7-'MLB Archetypes'!$C$18)^2+(I7-'MLB Archetypes'!$D$18)^2+(J7-'MLB Archetypes'!$E$18)^2+(K7-'MLB Archetypes'!$F$18)^2) -> 4.7958315 | BC7: =SQRT((H7-'MLB Archetypes'!$C$19)^2+(I7-'MLB Archetypes'!$D$19)^2+(J7-'MLB Archetypes'!$E$19)^2+(K7-'MLB Archetypes'!$F$19)^2) -> 7.2111026 | BD7: =INDEX('MLB Archetypes'!$B$2:$B$19,MATCH(MIN(AL7:BC7),AL7:BC7,0)) -> Albert Pujols | BE7: =ROUND(10-MIN(AL7:BC7)/1.8,1) -> 7.6
A8: Luigi | B8: Luigi Knights | C8: Luigi | D8: No | E8: Yes | F8: Right | G8: Left | H8: 6 | I8: 6 | J8: 7 | K8: 7 | L8: =H8+I8+J8+K8 -> 26 | M8: =ROUND(0.75*I8+0.25*K8,2) -> 6.25 | N8: =ROUND(0.7*J8+0.3*K8,2) -> 7 | O8: =ROUND((H8+J8+K8)/3,2) -> 6.67 | P8: =ROUND(0.85*H8+0.15*J8,2) -> 6.15 | Q8: =ROUND(0.6*J8+0.3*I8+0.1*H8,2) -> 6.6 | R8: =ROUND(0.7*I8+0.2*J8+0.1*K8,2) -> 6.3 | S8: =ROUND(0.13*I8+0.35*J8+0.52*K8,2) -> 6.87 | T8: =ROUND(0.4*I8+0.5*J8+0.1*K8,2) -> 6.6 | U8: =ROUND(0.1*I8+0.55*J8+0.35*K8,2) -> 6.9 | V8: =ROUND(0.6*I8+0.1*J8+0.3*K8,2) -> 6.4 | W8: =ROUND(0.15*I8+0.3*J8+0.55*K8,2) -> 6.85 | X8: =ROUND(0.46*I8+0.46*J8+0.08*K8,2) -> 6.54 | Y8: =IF(H8=MAX(H8:K8),"Pitcher (arm-first)",IF(I8=MAX(H8:K8),"Bat-first (corner/1B/DH)",IF(J8=MAX(H8:K8),"Defense-first (up-the-middle)","Speed-first (CF/leadoff)"))) -> Defense-first (up-the-middle) | Z8: =P8 -> 6.15 | AA8: =IF(F8="Right",Q8,-1) -> 6.6 | AB8: =R8 -> 6.3 | AC8: =IF(F8="Right",S8,-1) -> 6.87 | AD8: =IF(F8="Right",T8,-1) -> 6.6 | AE8: =IF(F8="Right",U8,-1) -> 6.9 | AF8: =V8 -> 6.4 | AG8: =W8 -> 6.85 | AH8: =X8 -> 6.54 | AI8: =INDEX($Z$1:$AH$1,MATCH(MAX(Z8:AH8),Z8:AH8,0)) -> SS | AJ8: =MAX(Z8:AH8) -> 6.9 | AK8: =SUMPRODUCT(($AI$2:$AI$73=AI8)*($AJ$2:$AJ$73>AJ8))+SUMPRODUCT(($AI$2:$AI$73=AI8)*($AJ$2:$AJ$73=AJ8)*(ROW($AI$2:$AI$73)<ROW(AI8)))+1 -> 2 | AL8: =SQRT((H8-'MLB Archetypes'!$C$2)^2+(I8-'MLB Archetypes'!$D$2)^2+(J8-'MLB Archetypes'!$E$2)^2+(K8-'MLB Archetypes'!$F$2)^2) -> 7.2111026 | AM8: =SQRT((H8-'MLB Archetypes'!$C$3)^2+(I8-'MLB Archetypes'!$D$3)^2+(J8-'MLB Archetypes'!$E$3)^2+(K8-'MLB Archetypes'!$F$3)^2) -> 5.9160798 | AN8: =SQRT((H8-'MLB Archetypes'!$C$4)^2+(I8-'MLB Archetypes'!$D$4)^2+(J8-'MLB Archetypes'!$E$4)^2+(K8-'MLB Archetypes'!$F$4)^2) -> 6.0827625 | AO8: =SQRT((H8-'MLB Archetypes'!$C$5)^2+(I8-'MLB Archetypes'!$D$5)^2+(J8-'MLB Archetypes'!$E$5)^2+(K8-'MLB Archetypes'!$F$5)^2) -> 5.0990195 | AP8: =SQRT((H8-'MLB Archetypes'!$C$6)^2+(I8-'MLB Archetypes'!$D$6)^2+(J8-'MLB Archetypes'!$E$6)^2+(K8-'MLB Archetypes'!$F$6)^2) -> 6.4807407 | AQ8: =SQRT((H8-'MLB Archetypes'!$C$7)^2+(I8-'MLB Archetypes'!$D$7)^2+(J8-'MLB Archetypes'!$E$7)^2+(K8-'MLB Archetypes'!$F$7)^2) -> 5.3851648 | AR8: =SQRT((H8-'MLB Archetypes'!$C$8)^2+(I8-'MLB Archetypes'!$D$8)^2+(J8-'MLB Archetypes'!$E$8)^2+(K8-'MLB Archetypes'!$F$8)^2) -> 4.1231056 | AS8: =SQRT((H8-'MLB Archetypes'!$C$9)^2+(I8-'MLB Archetypes'!$D$9)^2+(J8-'MLB Archetypes'!$E$9)^2+(K8-'MLB Archetypes'!$F$9)^2) -> 4.3588989 | AT8: =SQRT((H8-'MLB Archetypes'!$C$10)^2+(I8-'MLB Archetypes'!$D$10)^2+(J8-'MLB Archetypes'!$E$10)^2+(K8-'MLB Archetypes'!$F$10)^2) -> 5.4772256 | AU8: =SQRT((H8-'MLB Archetypes'!$C$11)^2+(I8-'MLB Archetypes'!$D$11)^2+(J8-'MLB Archetypes'!$E$11)^2+(K8-'MLB Archetypes'!$F$11)^2) -> 5.9160798 | AV8: =SQRT((H8-'MLB Archetypes'!$C$12)^2+(I8-'MLB Archetypes'!$D$12)^2+(J8-'MLB Archetypes'!$E$12)^2+(K8-'MLB Archetypes'!$F$12)^2) -> 5.8309519 | AW8: =SQRT((H8-'MLB Archetypes'!$C$13)^2+(I8-'MLB Archetypes'!$D$13)^2+(J8-'MLB Archetypes'!$E$13)^2+(K8-'MLB Archetypes'!$F$13)^2) -> 5.7445626 | AX8: =SQRT((H8-'MLB Archetypes'!$C$14)^2+(I8-'MLB Archetypes'!$D$14)^2+(J8-'MLB Archetypes'!$E$14)^2+(K8-'MLB Archetypes'!$F$14)^2) -> 5.4772256 | AY8: =SQRT((H8-'MLB Archetypes'!$C$15)^2+(I8-'MLB Archetypes'!$D$15)^2+(J8-'MLB Archetypes'!$E$15)^2+(K8-'MLB Archetypes'!$F$15)^2) -> 5.3851648 | AZ8: =SQRT((H8-'MLB Archetypes'!$C$16)^2+(I8-'MLB Archetypes'!$D$16)^2+(J8-'MLB Archetypes'!$E$16)^2+(K8-'MLB Archetypes'!$F$16)^2) -> 5 | BA8: =SQRT((H8-'MLB Archetypes'!$C$17)^2+(I8-'MLB Archetypes'!$D$17)^2+(J8-'MLB Archetypes'!$E$17)^2+(K8-'MLB Archetypes'!$F$17)^2) -> 4.5825757 | BB8: =SQRT((H8-'MLB Archetypes'!$C$18)^2+(I8-'MLB Archetypes'!$D$18)^2+(J8-'MLB Archetypes'!$E$18)^2+(K8-'MLB Archetypes'!$F$18)^2) -> 5.4772256 | BC8: =SQRT((H8-'MLB Archetypes'!$C$19)^2+(I8-'MLB Archetypes'!$D$19)^2+(J8-'MLB Archetypes'!$E$19)^2+(K8-'MLB Archetypes'!$F$19)^2) -> 4.3588989 | BD8: =INDEX('MLB Archetypes'!$B$2:$B$19,MATCH(MIN(AL8:BC8),AL8:BC8,0)) -> Jackie Robinson | BE8: =ROUND(10-MIN(AL8:BC8)/1.8,1) -> 7.7
A9: Daisy | B9: Daisy Flowers | C9: Daisy | D9: No | E9: Yes | F9: Right | G9: Left | H9: 7 | I9: 6 | J9: 8 | K9: 5 | L9: =H9+I9+J9+K9 -> 26 | M9: =ROUND(0.75*I9+0.25*K9,2) -> 5.75 | N9: =ROUND(0.7*J9+0.3*K9,2) -> 7.1 | O9: =ROUND((H9+J9+K9)/3,2) -> 6.67 | P9: =ROUND(0.85*H9+0.15*J9,2) -> 7.15 | Q9: =ROUND(0.6*J9+0.3*I9+0.1*H9,2) -> 7.3 | R9: =ROUND(0.7*I9+0.2*J9+0.1*K9,2) -> 6.3 | S9: =ROUND(0.13*I9+0.35*J9+0.52*K9,2) -> 6.18 | T9: =ROUND(0.4*I9+0.5*J9+0.1*K9,2) -> 6.9 | U9: =ROUND(0.1*I9+0.55*J9+0.35*K9,2) -> 6.75 | V9: =ROUND(0.6*I9+0.1*J9+0.3*K9,2) -> 5.9 | W9: =ROUND(0.15*I9+0.3*J9+0.55*K9,2) -> 6.05 | X9: =ROUND(0.46*I9+0.46*J9+0.08*K9,2) -> 6.84 | Y9: =IF(H9=MAX(H9:K9),"Pitcher (arm-first)",IF(I9=MAX(H9:K9),"Bat-first (corner/1B/DH)",IF(J9=MAX(H9:K9),"Defense-first (up-the-middle)","Speed-first (CF/leadoff)"))) -> Defense-first (up-the-middle) | Z9: =P9 -> 7.15 | AA9: =IF(F9="Right",Q9,-1) -> 7.3 | AB9: =R9 -> 6.3 | AC9: =IF(F9="Right",S9,-1) -> 6.18 | AD9: =IF(F9="Right",T9,-1) -> 6.9 | AE9: =IF(F9="Right",U9,-1) -> 6.75 | AF9: =V9 -> 5.9 | AG9: =W9 -> 6.05 | AH9: =X9 -> 6.84 | AI9: =INDEX($Z$1:$AH$1,MATCH(MAX(Z9:AH9),Z9:AH9,0)) -> C | AJ9: =MAX(Z9:AH9) -> 7.3 | AK9: =SUMPRODUCT(($AI$2:$AI$73=AI9)*($AJ$2:$AJ$73>AJ9))+SUMPRODUCT(($AI$2:$AI$73=AI9)*($AJ$2:$AJ$73=AJ9)*(ROW($AI$2:$AI$73)<ROW(AI9)))+1 -> 1 | AL9: =SQRT((H9-'MLB Archetypes'!$C$2)^2+(I9-'MLB Archetypes'!$D$2)^2+(J9-'MLB Archetypes'!$E$2)^2+(K9-'MLB Archetypes'!$F$2)^2) -> 6.164414 | AM9: =SQRT((H9-'MLB Archetypes'!$C$3)^2+(I9-'MLB Archetypes'!$D$3)^2+(J9-'MLB Archetypes'!$E$3)^2+(K9-'MLB Archetypes'!$F$3)^2) -> 4.5825757 | AN9: =SQRT((H9-'MLB Archetypes'!$C$4)^2+(I9-'MLB Archetypes'!$D$4)^2+(J9-'MLB Archetypes'!$E$4)^2+(K9-'MLB Archetypes'!$F$4)^2) -> 5.5677644 | AO9: =SQRT((H9-'MLB Archetypes'!$C$5)^2+(I9-'MLB Archetypes'!$D$5)^2+(J9-'MLB Archetypes'!$E$5)^2+(K9-'MLB Archetypes'!$F$5)^2) -> 5.0990195 | AP9: =SQRT((H9-'MLB Archetypes'!$C$6)^2+(I9-'MLB Archetypes'!$D$6)^2+(J9-'MLB Archetypes'!$E$6)^2+(K9-'MLB Archetypes'!$F$6)^2) -> 6.4807407 | AQ9: =SQRT((H9-'MLB Archetypes'!$C$7)^2+(I9-'MLB Archetypes'!$D$7)^2+(J9-'MLB Archetypes'!$E$7)^2+(K9-'MLB Archetypes'!$F$7)^2) -> 5.1961524 | AR9: =SQRT((H9-'MLB Archetypes'!$C$8)^2+(I9-'MLB Archetypes'!$D$8)^2+(J9-'MLB Archetypes'!$E$8)^2+(K9-'MLB Archetypes'!$F$8)^2) -> 5.9160798 | AS9: =SQRT((H9-'MLB Archetypes'!$C$9)^2+(I9-'MLB Archetypes'!$D$9)^2+(J9-'MLB Archetypes'!$E$9)^2+(K9-'MLB Archetypes'!$F$9)^2) -> 5.1961524 | AT9: =SQRT((H9-'MLB Archetypes'!$C$10)^2+(I9-'MLB Archetypes'!$D$10)^2+(J9-'MLB Archetypes'!$E$10)^2+(K9-'MLB Archetypes'!$F$10)^2) -> 5.4772256 | AU9: =SQRT((H9-'MLB Archetypes'!$C$11)^2+(I9-'MLB Archetypes'!$D$11)^2+(J9-'MLB Archetypes'!$E$11)^2+(K9-'MLB Archetypes'!$F$11)^2) -> 6.244998 | AV9: =SQRT((H9-'MLB Archetypes'!$C$12)^2+(I9-'MLB Archetypes'!$D$12)^2+(J9-'MLB Archetypes'!$E$12)^2+(K9-'MLB Archetypes'!$F$12)^2) -> 6.4807407 | AW9: =SQRT((H9-'MLB Archetypes'!$C$13)^2+(I9-'MLB Archetypes'!$D$13)^2+(J9-'MLB Archetypes'!$E$13)^2+(K9-'MLB Archetypes'!$F$13)^2) -> 5.5677644 | AX9: =SQRT((H9-'MLB Archetypes'!$C$14)^2+(I9-'MLB Archetypes'!$D$14)^2+(J9-'MLB Archetypes'!$E$14)^2+(K9-'MLB Archetypes'!$F$14)^2) -> 6.164414 | AY9: =SQRT((H9-'MLB Archetypes'!$C$15)^2+(I9-'MLB Archetypes'!$D$15)^2+(J9-'MLB Archetypes'!$E$15)^2+(K9-'MLB Archetypes'!$F$15)^2) -> 7.6811457 | AZ9: =SQRT((H9-'MLB Archetypes'!$C$16)^2+(I9-'MLB Archetypes'!$D$16)^2+(J9-'MLB Archetypes'!$E$16)^2+(K9-'MLB Archetypes'!$F$16)^2) -> 6.244998 | BA9: =SQRT((H9-'MLB Archetypes'!$C$17)^2+(I9-'MLB Archetypes'!$D$17)^2+(J9-'MLB Archetypes'!$E$17)^2+(K9-'MLB Archetypes'!$F$17)^2) -> 6.5574385 | BB9: =SQRT((H9-'MLB Archetypes'!$C$18)^2+(I9-'MLB Archetypes'!$D$18)^2+(J9-'MLB Archetypes'!$E$18)^2+(K9-'MLB Archetypes'!$F$18)^2) -> 6.164414 | BC9: =SQRT((H9-'MLB Archetypes'!$C$19)^2+(I9-'MLB Archetypes'!$D$19)^2+(J9-'MLB Archetypes'!$E$19)^2+(K9-'MLB Archetypes'!$F$19)^2) -> 5.1961524 | BD9: =INDEX('MLB Archetypes'!$B$2:$B$19,MATCH(MIN(AL9:BC9),AL9:BC9,0)) -> Greg Maddux | BE9: =ROUND(10-MIN(AL9:BC9)/1.8,1) -> 7.5
A10: Birdo | B10: Birdo Bows | C10: Birdo | D10: No | E10: Yes | F10: Right | G10: Right | H10: 4 | I10: 8 | J10: 7 | K10: 5 | L10: =H10+I10+J10+K10 -> 24 | M10: =ROUND(0.75*I10+0.25*K10,2) -> 7.25 | N10: =ROUND(0.7*J10+0.3*K10,2) -> 6.4 | O10: =ROUND((H10+J10+K10)/3,2) -> 5.33 | P10: =ROUND(0.85*H10+0.15*J10,2) -> 4.45 | Q10: =ROUND(0.6*J10+0.3*I10+0.1*H10,2) -> 7 | R10: =ROUND(0.7*I10+0.2*J10+0.1*K10,2) -> 7.5 | S10: =ROUND(0.13*I10+0.35*J10+0.52*K10,2) -> 6.09 | T10: =ROUND(0.4*I10+0.5*J10+0.1*K10,2) -> 7.2 | U10: =ROUND(0.1*I10+0.55*J10+0.35*K10,2) -> 6.4 | V10: =ROUND(0.6*I10+0.1*J10+0.3*K10,2) -> 7 | W10: =ROUND(0.15*I10+0.3*J10+0.55*K10,2) -> 6.05 | X10: =ROUND(0.46*I10+0.46*J10+0.08*K10,2) -> 7.3 | Y10: =IF(H10=MAX(H10:K10),"Pitcher (arm-first)",IF(I10=MAX(H10:K10),"Bat-first (corner/1B/DH)",IF(J10=MAX(H10:K10),"Defense-first (up-the-middle)","Speed-first (CF/leadoff)"))) -> Bat-first (corner/1B/DH) | Z10: =P10 -> 4.45 | AA10: =IF(F10="Right",Q10,-1) -> 7 | AB10: =R10 -> 7.5 | AC10: =IF(F10="Right",S10,-1) -> 6.09 | AD10: =IF(F10="Right",T10,-1) -> 7.2 | AE10: =IF(F10="Right",U10,-1) -> 6.4 | AF10: =V10 -> 7 | AG10: =W10 -> 6.05 | AH10: =X10 -> 7.3 | AI10: =INDEX($Z$1:$AH$1,MATCH(MAX(Z10:AH10),Z10:AH10,0)) -> 1B | AJ10: =MAX(Z10:AH10) -> 7.5 | AK10: =SUMPRODUCT(($AI$2:$AI$73=AI10)*($AJ$2:$AJ$73>AJ10))+SUMPRODUCT(($AI$2:$AI$73=AI10)*($AJ$2:$AJ$73=AJ10)*(ROW($AI$2:$AI$73)<ROW(AI10)))+1 -> 3 | AL10: =SQRT((H10-'MLB Archetypes'!$C$2)^2+(I10-'MLB Archetypes'!$D$2)^2+(J10-'MLB Archetypes'!$E$2)^2+(K10-'MLB Archetypes'!$F$2)^2) -> 8.9442719 | AM10: =SQRT((H10-'MLB Archetypes'!$C$3)^2+(I10-'MLB Archetypes'!$D$3)^2+(J10-'MLB Archetypes'!$E$3)^2+(K10-'MLB Archetypes'!$F$3)^2) -> 7.4161985 | AN10: =SQRT((H10-'MLB Archetypes'!$C$4)^2+(I10-'MLB Archetypes'!$D$4)^2+(J10-'MLB Archetypes'!$E$4)^2+(K10-'MLB Archetypes'!$F$4)^2) -> 3.6055513 | AO10: =SQRT((H10-'MLB Archetypes'!$C$5)^2+(I10-'MLB Archetypes'!$D$5)^2+(J10-'MLB Archetypes'!$E$5)^2+(K10-'MLB Archetypes'!$F$5)^2) -> 3.1622777 | AP10: =SQRT((H10-'MLB Archetypes'!$C$6)^2+(I10-'MLB Archetypes'!$D$6)^2+(J10-'MLB Archetypes'!$E$6)^2+(K10-'MLB Archetypes'!$F$6)^2) -> 3.1622777 | AQ10: =SQRT((H10-'MLB Archetypes'!$C$7)^2+(I10-'MLB Archetypes'!$D$7)^2+(J10-'MLB Archetypes'!$E$7)^2+(K10-'MLB Archetypes'!$F$7)^2) -> 3.6055513 | AR10: =SQRT((H10-'MLB Archetypes'!$C$8)^2+(I10-'MLB Archetypes'!$D$8)^2+(J10-'MLB Archetypes'!$E$8)^2+(K10-'MLB Archetypes'!$F$8)^2) -> 4.1231056 | AS10: =SQRT((H10-'MLB Archetypes'!$C$9)^2+(I10-'MLB Archetypes'!$D$9)^2+(J10-'MLB Archetypes'!$E$9)^2+(K10-'MLB Archetypes'!$F$9)^2) -> 2.6457513 | AT10: =SQRT((H10-'MLB Archetypes'!$C$10)^2+(I10-'MLB Archetypes'!$D$10)^2+(J10-'MLB Archetypes'!$E$10)^2+(K10-'MLB Archetypes'!$F$10)^2) -> 2.4494897 | AU10: =SQRT((H10-'MLB Archetypes'!$C$11)^2+(I10-'MLB Archetypes'!$D$11)^2+(J10-'MLB Archetypes'!$E$11)^2+(K10-'MLB Archetypes'!$F$11)^2) -> 2.6457513 | AV10: =SQRT((H10-'MLB Archetypes'!$C$12)^2+(I10-'MLB Archetypes'!$D$12)^2+(J10-'MLB Archetypes'!$E$12)^2+(K10-'MLB Archetypes'!$F$12)^2) -> 6.4807407 | AW10: =SQRT((H10-'MLB Archetypes'!$C$13)^2+(I10-'MLB Archetypes'!$D$13)^2+(J10-'MLB Archetypes'!$E$13)^2+(K10-'MLB Archetypes'!$F$13)^2) -> 3 | AX10: =SQRT((H10-'MLB Archetypes'!$C$14)^2+(I10-'MLB Archetypes'!$D$14)^2+(J10-'MLB Archetypes'!$E$14)^2+(K10-'MLB Archetypes'!$F$14)^2) -> 2.4494897 | AY10: =SQRT((H10-'MLB Archetypes'!$C$15)^2+(I10-'MLB Archetypes'!$D$15)^2+(J10-'MLB Archetypes'!$E$15)^2+(K10-'MLB Archetypes'!$F$15)^2) -> 6.0827625 | AZ10: =SQRT((H10-'MLB Archetypes'!$C$16)^2+(I10-'MLB Archetypes'!$D$16)^2+(J10-'MLB Archetypes'!$E$16)^2+(K10-'MLB Archetypes'!$F$16)^2) -> 4.1231056 | BA10: =SQRT((H10-'MLB Archetypes'!$C$17)^2+(I10-'MLB Archetypes'!$D$17)^2+(J10-'MLB Archetypes'!$E$17)^2+(K10-'MLB Archetypes'!$F$17)^2) -> 4.5825757 | BB10: =SQRT((H10-'MLB Archetypes'!$C$18)^2+(I10-'MLB Archetypes'!$D$18)^2+(J10-'MLB Archetypes'!$E$18)^2+(K10-'MLB Archetypes'!$F$18)^2) -> 2.4494897 | BC10: =SQRT((H10-'MLB Archetypes'!$C$19)^2+(I10-'MLB Archetypes'!$D$19)^2+(J10-'MLB Archetypes'!$E$19)^2+(K10-'MLB Archetypes'!$F$19)^2) -> 2.6457513 | BD10: =INDEX('MLB Archetypes'!$B$2:$B$19,MATCH(MIN(AL10:BC10),AL10:BC10,0)) -> Mike Schmidt | BE10: =ROUND(10-MIN(AL10:BC10)/1.8,1) -> 8.6
A11: Waluigi | B11: Waluigi Spitballs | C11: Waluigi | D11: No | E11: Yes | F11: Left | G11: Left | H11: 8 | I11: 4 | J11: 8 | K11: 5 | L11: =H11+I11+J11+K11 -> 25 | M11: =ROUND(0.75*I11+0.25*K11,2) -> 4.25 | N11: =ROUND(0.7*J11+0.3*K11,2) -> 7.1 | O11: =ROUND((H11+J11+K11)/3,2) -> 7 | P11: =ROUND(0.85*H11+0.15*J11,2) -> 8 | Q11: =ROUND(0.6*J11+0.3*I11+0.1*H11,2) -> 6.8 | R11: =ROUND(0.7*I11+0.2*J11+0.1*K11,2) -> 4.9 | S11: =ROUND(0.13*I11+0.35*J11+0.52*K11,2) -> 5.92 | T11: =ROUND(0.4*I11+0.5*J11+0.1*K11,2) -> 6.1 | U11: =ROUND(0.1*I11+0.55*J11+0.35*K11,2) -> 6.55 | V11: =ROUND(0.6*I11+0.1*J11+0.3*K11,2) -> 4.7 | W11: =ROUND(0.15*I11+0.3*J11+0.55*K11,2) -> 5.75 | X11: =ROUND(0.46*I11+0.46*J11+0.08*K11,2) -> 5.92 | Y11: =IF(H11=MAX(H11:K11),"Pitcher (arm-first)",IF(I11=MAX(H11:K11),"Bat-first (corner/1B/DH)",IF(J11=MAX(H11:K11),"Defense-first (up-the-middle)","Speed-first (CF/leadoff)"))) -> Pitcher (arm-first) | Z11: =P11 -> 8 | AA11: =IF(F11="Right",Q11,-1) -> -1 | AB11: =R11 -> 4.9 | AC11: =IF(F11="Right",S11,-1) -> -1 | AD11: =IF(F11="Right",T11,-1) -> -1 | AE11: =IF(F11="Right",U11,-1) -> -1 | AF11: =V11 -> 4.7 | AG11: =W11 -> 5.75 | AH11: =X11 -> 5.92 | AI11: =INDEX($Z$1:$AH$1,MATCH(MAX(Z11:AH11),Z11:AH11,0)) -> P | AJ11: =MAX(Z11:AH11) -> 8 | AK11: =SUMPRODUCT(($AI$2:$AI$73=AI11)*($AJ$2:$AJ$73>AJ11))+SUMPRODUCT(($AI$2:$AI$73=AI11)*($AJ$2:$AJ$73=AJ11)*(ROW($AI$2:$AI$73)<ROW(AI11)))+1 -> 3 | AL11: =SQRT((H11-'MLB Archetypes'!$C$2)^2+(I11-'MLB Archetypes'!$D$2)^2+(J11-'MLB Archetypes'!$E$2)^2+(K11-'MLB Archetypes'!$F$2)^2) -> 4.5825757 | AM11: =SQRT((H11-'MLB Archetypes'!$C$3)^2+(I11-'MLB Archetypes'!$D$3)^2+(J11-'MLB Archetypes'!$E$3)^2+(K11-'MLB Archetypes'!$F$3)^2) -> 3.1622777 | AN11: =SQRT((H11-'MLB Archetypes'!$C$4)^2+(I11-'MLB Archetypes'!$D$4)^2+(J11-'MLB Archetypes'!$E$4)^2+(K11-'MLB Archetypes'!$F$4)^2) -> 7.0710678 | AO11: =SQRT((H11-'MLB Archetypes'!$C$5)^2+(I11-'MLB Archetypes'!$D$5)^2+(J11-'MLB Archetypes'!$E$5)^2+(K11-'MLB Archetypes'!$F$5)^2) -> 6.4031242 | AP11: =SQRT((H11-'MLB Archetypes'!$C$6)^2+(I11-'MLB Archetypes'!$D$6)^2+(J11-'MLB Archetypes'!$E$6)^2+(K11-'MLB Archetypes'!$F$6)^2) -> 8.3066239 | AQ11: =SQRT((H11-'MLB Archetypes'!$C$7)^2+(I11-'MLB Archetypes'!$D$7)^2+(J11-'MLB Archetypes'!$E$7)^2+(K11-'MLB Archetypes'!$F$7)^2) -> 6.4807407 | AR11: =SQRT((H11-'MLB Archetypes'!$C$8)^2+(I11-'MLB Archetypes'!$D$8)^2+(J11-'MLB Archetypes'!$E$8)^2+(K11-'MLB Archetypes'!$F$8)^2) -> 7.0710678 | AS11: =SQRT((H11-'MLB Archetypes'!$C$9)^2+(I11-'MLB Archetypes'!$D$9)^2+(J11-'MLB Archetypes'!$E$9)^2+(K11-'MLB Archetypes'!$F$9)^2) -> 6.78233 | AT11: =SQRT((H11-'MLB Archetypes'!$C$10)^2+(I11-'MLB Archetypes'!$D$10)^2+(J11-'MLB Archetypes'!$E$10)^2+(K11-'MLB Archetypes'!$F$10)^2) -> 7.2801099 | AU11: =SQRT((H11-'MLB Archetypes'!$C$11)^2+(I11-'MLB Archetypes'!$D$11)^2+(J11-'MLB Archetypes'!$E$11)^2+(K11-'MLB Archetypes'!$F$11)^2) -> 8.1240384 | AV11: =SQRT((H11-'MLB Archetypes'!$C$12)^2+(I11-'MLB Archetypes'!$D$12)^2+(J11-'MLB Archetypes'!$E$12)^2+(K11-'MLB Archetypes'!$F$12)^2) -> 6.7082039 | AW11: =SQRT((H11-'MLB Archetypes'!$C$13)^2+(I11-'MLB Archetypes'!$D$13)^2+(J11-'MLB Archetypes'!$E$13)^2+(K11-'MLB Archetypes'!$F$13)^2) -> 7.0710678 | AX11: =SQRT((H11-'MLB Archetypes'!$C$14)^2+(I11-'MLB Archetypes'!$D$14)^2+(J11-'MLB Archetypes'!$E$14)^2+(K11-'MLB Archetypes'!$F$14)^2) -> 8.0622577 | AY11: =SQRT((H11-'MLB Archetypes'!$C$15)^2+(I11-'MLB Archetypes'!$D$15)^2+(J11-'MLB Archetypes'!$E$15)^2+(K11-'MLB Archetypes'!$F$15)^2) -> 8.6023253 | AZ11: =SQRT((H11-'MLB Archetypes'!$C$16)^2+(I11-'MLB Archetypes'!$D$16)^2+(J11-'MLB Archetypes'!$E$16)^2+(K11-'MLB Archetypes'!$F$16)^2) -> 7.8740079 | BA11: =SQRT((H11-'MLB Archetypes'!$C$17)^2+(I11-'MLB Archetypes'!$D$17)^2+(J11-'MLB Archetypes'!$E$17)^2+(K11-'MLB Archetypes'!$F$17)^2) -> 7.8740079 | BB11: =SQRT((H11-'MLB Archetypes'!$C$18)^2+(I11-'MLB Archetypes'!$D$18)^2+(J11-'MLB Archetypes'!$E$18)^2+(K11-'MLB Archetypes'!$F$18)^2) -> 8.0622577 | BC11: =SQRT((H11-'MLB Archetypes'!$C$19)^2+(I11-'MLB Archetypes'!$D$19)^2+(J11-'MLB Archetypes'!$E$19)^2+(K11-'MLB Archetypes'!$F$19)^2) -> 6.78233 | BD11: =INDEX('MLB Archetypes'!$B$2:$B$19,MATCH(MIN(AL11:BC11),AL11:BC11,0)) -> Greg Maddux | BE11: =ROUND(10-MIN(AL11:BC11)/1.8,1) -> 8.2
A12: Diddy Kong | B12: Diddy Monkeys | C12: Diddy Kong | D12: No | E12: Yes | F12: Right | G12: Left | H12: 5 | I12: 4 | J12: 8 | K12: 6 | L12: =H12+I12+J12+K12 -> 23 | M12: =ROUND(0.75*I12+0.25*K12,2) -> 4.5 | N12: =ROUND(0.7*J12+0.3*K12,2) -> 7.4 | O12: =ROUND((H12+J12+K12)/3,2) -> 6.33 | P12: =ROUND(0.85*H12+0.15*J12,2) -> 5.45 | Q12: =ROUND(0.6*J12+0.3*I12+0.1*H12,2) -> 6.5 | R12: =ROUND(0.7*I12+0.2*J12+0.1*K12,2) -> 5 | S12: =ROUND(0.13*I12+0.35*J12+0.52*K12,2) -> 6.44 | T12: =ROUND(0.4*I12+0.5*J12+0.1*K12,2) -> 6.2 | U12: =ROUND(0.1*I12+0.55*J12+0.35*K12,2) -> 6.9 | V12: =ROUND(0.6*I12+0.1*J12+0.3*K12,2) -> 5 | W12: =ROUND(0.15*I12+0.3*J12+0.55*K12,2) -> 6.3 | X12: =ROUND(0.46*I12+0.46*J12+0.08*K12,2) -> 6 | Y12: =IF(H12=MAX(H12:K12),"Pitcher (arm-first)",IF(I12=MAX(H12:K12),"Bat-first (corner/1B/DH)",IF(J12=MAX(H12:K12),"Defense-first (up-the-middle)","Speed-first (CF/leadoff)"))) -> Defense-first (up-the-middle) | Z12: =P12 -> 5.45 | AA12: =IF(F12="Right",Q12,-1) -> 6.5 | AB12: =R12 -> 5 | AC12: =IF(F12="Right",S12,-1) -> 6.44 | AD12: =IF(F12="Right",T12,-1) -> 6.2 | AE12: =IF(F12="Right",U12,-1) -> 6.9 | AF12: =V12 -> 5 | AG12: =W12 -> 6.3 | AH12: =X12 -> 6 | AI12: =INDEX($Z$1:$AH$1,MATCH(MAX(Z12:AH12),Z12:AH12,0)) -> SS | AJ12: =MAX(Z12:AH12) -> 6.9 | AK12: =SUMPRODUCT(($AI$2:$AI$73=AI12)*($AJ$2:$AJ$73>AJ12))+SUMPRODUCT(($AI$2:$AI$73=AI12)*($AJ$2:$AJ$73=AJ12)*(ROW($AI$2:$AI$73)<ROW(AI12)))+1 -> 3 | AL12: =SQRT((H12-'MLB Archetypes'!$C$2)^2+(I12-'MLB Archetypes'!$D$2)^2+(J12-'MLB Archetypes'!$E$2)^2+(K12-'MLB Archetypes'!$F$2)^2) -> 6.8556546 | AM12: =SQRT((H12-'MLB Archetypes'!$C$3)^2+(I12-'MLB Archetypes'!$D$3)^2+(J12-'MLB Archetypes'!$E$3)^2+(K12-'MLB Archetypes'!$F$3)^2) -> 5.4772256 | AN12: =SQRT((H12-'MLB Archetypes'!$C$4)^2+(I12-'MLB Archetypes'!$D$4)^2+(J12-'MLB Archetypes'!$E$4)^2+(K12-'MLB Archetypes'!$F$4)^2) -> 5.2915026 | AO12: =SQRT((H12-'MLB Archetypes'!$C$5)^2+(I12-'MLB Archetypes'!$D$5)^2+(J12-'MLB Archetypes'!$E$5)^2+(K12-'MLB Archetypes'!$F$5)^2) -> 4.1231056 | AP12: =SQRT((H12-'MLB Archetypes'!$C$6)^2+(I12-'MLB Archetypes'!$D$6)^2+(J12-'MLB Archetypes'!$E$6)^2+(K12-'MLB Archetypes'!$F$6)^2) -> 6.8556546 | AQ12: =SQRT((H12-'MLB Archetypes'!$C$7)^2+(I12-'MLB Archetypes'!$D$7)^2+(J12-'MLB Archetypes'!$E$7)^2+(K12-'MLB Archetypes'!$F$7)^2) -> 4.2426407 | AR12: =SQRT((H12-'MLB Archetypes'!$C$8)^2+(I12-'MLB Archetypes'!$D$8)^2+(J12-'MLB Archetypes'!$E$8)^2+(K12-'MLB Archetypes'!$F$8)^2) -> 4.2426407 | AS12: =SQRT((H12-'MLB Archetypes'!$C$9)^2+(I12-'MLB Archetypes'!$D$9)^2+(J12-'MLB Archetypes'!$E$9)^2+(K12-'MLB Archetypes'!$F$9)^2) -> 4.2426407 | AT12: =SQRT((H12-'MLB Archetypes'!$C$10)^2+(I12-'MLB Archetypes'!$D$10)^2+(J12-'MLB Archetypes'!$E$10)^2+(K12-'MLB Archetypes'!$F$10)^2) -> 5.3851648 | AU12: =SQRT((H12-'MLB Archetypes'!$C$11)^2+(I12-'MLB Archetypes'!$D$11)^2+(J12-'MLB Archetypes'!$E$11)^2+(K12-'MLB Archetypes'!$F$11)^2) -> 6.4807407 | AV12: =SQRT((H12-'MLB Archetypes'!$C$12)^2+(I12-'MLB Archetypes'!$D$12)^2+(J12-'MLB Archetypes'!$E$12)^2+(K12-'MLB Archetypes'!$F$12)^2) -> 3.8729833 | AW12: =SQRT((H12-'MLB Archetypes'!$C$13)^2+(I12-'MLB Archetypes'!$D$13)^2+(J12-'MLB Archetypes'!$E$13)^2+(K12-'MLB Archetypes'!$F$13)^2) -> 5.2915026 | AX12: =SQRT((H12-'MLB Archetypes'!$C$14)^2+(I12-'MLB Archetypes'!$D$14)^2+(J12-'MLB Archetypes'!$E$14)^2+(K12-'MLB Archetypes'!$F$14)^2) -> 6.244998 | AY12: =SQRT((H12-'MLB Archetypes'!$C$15)^2+(I12-'MLB Archetypes'!$D$15)^2+(J12-'MLB Archetypes'!$E$15)^2+(K12-'MLB Archetypes'!$F$15)^2) -> 6.164414 | AZ12: =SQRT((H12-'MLB Archetypes'!$C$16)^2+(I12-'MLB Archetypes'!$D$16)^2+(J12-'MLB Archetypes'!$E$16)^2+(K12-'MLB Archetypes'!$F$16)^2) -> 5.4772256 | BA12: =SQRT((H12-'MLB Archetypes'!$C$17)^2+(I12-'MLB Archetypes'!$D$17)^2+(J12-'MLB Archetypes'!$E$17)^2+(K12-'MLB Archetypes'!$F$17)^2) -> 5.2915026 | BB12: =SQRT((H12-'MLB Archetypes'!$C$18)^2+(I12-'MLB Archetypes'!$D$18)^2+(J12-'MLB Archetypes'!$E$18)^2+(K12-'MLB Archetypes'!$F$18)^2) -> 6.244998 | BC12: =SQRT((H12-'MLB Archetypes'!$C$19)^2+(I12-'MLB Archetypes'!$D$19)^2+(J12-'MLB Archetypes'!$E$19)^2+(K12-'MLB Archetypes'!$F$19)^2) -> 4.2426407 | BD12: =INDEX('MLB Archetypes'!$B$2:$B$19,MATCH(MIN(AL12:BC12),AL12:BC12,0)) -> Ozzie Smith | BE12: =ROUND(10-MIN(AL12:BC12)/1.8,1) -> 7.8
A13: Bowser Jr. | B13: Bowser Jr. Rookies | C13: Bowser Jr. | D13: No | E13: Yes | F13: Left | G13: Right | H13: 5 | I13: 7 | J13: 4 | K13: 7 | L13: =H13+I13+J13+K13 -> 23 | M13: =ROUND(0.75*I13+0.25*K13,2) -> 7 | N13: =ROUND(0.7*J13+0.3*K13,2) -> 4.9 | O13: =ROUND((H13+J13+K13)/3,2) -> 5.33 | P13: =ROUND(0.85*H13+0.15*J13,2) -> 4.85 | Q13: =ROUND(0.6*J13+0.3*I13+0.1*H13,2) -> 5 | R13: =ROUND(0.7*I13+0.2*J13+0.1*K13,2) -> 6.4 | S13: =ROUND(0.13*I13+0.35*J13+0.52*K13,2) -> 5.95 | T13: =ROUND(0.4*I13+0.5*J13+0.1*K13,2) -> 5.5 | U13: =ROUND(0.1*I13+0.55*J13+0.35*K13,2) -> 5.35 | V13: =ROUND(0.6*I13+0.1*J13+0.3*K13,2) -> 6.7 | W13: =ROUND(0.15*I13+0.3*J13+0.55*K13,2) -> 6.1 | X13: =ROUND(0.46*I13+0.46*J13+0.08*K13,2) -> 5.62 | Y13: =IF(H13=MAX(H13:K13),"Pitcher (arm-first)",IF(I13=MAX(H13:K13),"Bat-first (corner/1B/DH)",IF(J13=MAX(H13:K13),"Defense-first (up-the-middle)","Speed-first (CF/leadoff)"))) -> Bat-first (corner/1B/DH) | Z13: =P13 -> 4.85 | AA13: =IF(F13="Right",Q13,-1) -> -1 | AB13: =R13 -> 6.4 | AC13: =IF(F13="Right",S13,-1) -> -1 | AD13: =IF(F13="Right",T13,-1) -> -1 | AE13: =IF(F13="Right",U13,-1) -> -1 | AF13: =V13 -> 6.7 | AG13: =W13 -> 6.1 | AH13: =X13 -> 5.62 | AI13: =INDEX($Z$1:$AH$1,MATCH(MAX(Z13:AH13),Z13:AH13,0)) -> LF | AJ13: =MAX(Z13:AH13) -> 6.7 | AK13: =SUMPRODUCT(($AI$2:$AI$73=AI13)*($AJ$2:$AJ$73>AJ13))+SUMPRODUCT(($AI$2:$AI$73=AI13)*($AJ$2:$AJ$73=AJ13)*(ROW($AI$2:$AI$73)<ROW(AI13)))+1 -> 2 | AL13: =SQRT((H13-'MLB Archetypes'!$C$2)^2+(I13-'MLB Archetypes'!$D$2)^2+(J13-'MLB Archetypes'!$E$2)^2+(K13-'MLB Archetypes'!$F$2)^2) -> 8.1853528 | AM13: =SQRT((H13-'MLB Archetypes'!$C$3)^2+(I13-'MLB Archetypes'!$D$3)^2+(J13-'MLB Archetypes'!$E$3)^2+(K13-'MLB Archetypes'!$F$3)^2) -> 7.2111026 | AN13: =SQRT((H13-'MLB Archetypes'!$C$4)^2+(I13-'MLB Archetypes'!$D$4)^2+(J13-'MLB Archetypes'!$E$4)^2+(K13-'MLB Archetypes'!$F$4)^2) -> 7.0710678 | AO13: =SQRT((H13-'MLB Archetypes'!$C$5)^2+(I13-'MLB Archetypes'!$D$5)^2+(J13-'MLB Archetypes'!$E$5)^2+(K13-'MLB Archetypes'!$F$5)^2) -> 5.9160798 | AP13: =SQRT((H13-'MLB Archetypes'!$C$6)^2+(I13-'MLB Archetypes'!$D$6)^2+(J13-'MLB Archetypes'!$E$6)^2+(K13-'MLB Archetypes'!$F$6)^2) -> 5.7445626 | AQ13: =SQRT((H13-'MLB Archetypes'!$C$7)^2+(I13-'MLB Archetypes'!$D$7)^2+(J13-'MLB Archetypes'!$E$7)^2+(K13-'MLB Archetypes'!$F$7)^2) -> 6.6332496 | AR13: =SQRT((H13-'MLB Archetypes'!$C$8)^2+(I13-'MLB Archetypes'!$D$8)^2+(J13-'MLB Archetypes'!$E$8)^2+(K13-'MLB Archetypes'!$F$8)^2) -> 4.472136 | AS13: =SQRT((H13-'MLB Archetypes'!$C$9)^2+(I13-'MLB Archetypes'!$D$9)^2+(J13-'MLB Archetypes'!$E$9)^2+(K13-'MLB Archetypes'!$F$9)^2) -> 5.0990195 | AT13: =SQRT((H13-'MLB Archetypes'!$C$10)^2+(I13-'MLB Archetypes'!$D$10)^2+(J13-'MLB Archetypes'!$E$10)^2+(K13-'MLB Archetypes'!$F$10)^2) -> 5.9160798 | AU13: =SQRT((H13-'MLB Archetypes'!$C$11)^2+(I13-'MLB Archetypes'!$D$11)^2+(J13-'MLB Archetypes'!$E$11)^2+(K13-'MLB Archetypes'!$F$11)^2) -> 5.0990195 | AV13: =SQRT((H13-'MLB Archetypes'!$C$12)^2+(I13-'MLB Archetypes'!$D$12)^2+(J13-'MLB Archetypes'!$E$12)^2+(K13-'MLB Archetypes'!$F$12)^2) -> 7.8102497 | AW13: =SQRT((H13-'MLB Archetypes'!$C$13)^2+(I13-'MLB Archetypes'!$D$13)^2+(J13-'MLB Archetypes'!$E$13)^2+(K13-'MLB Archetypes'!$F$13)^2) -> 5.8309519 | AX13: =SQRT((H13-'MLB Archetypes'!$C$14)^2+(I13-'MLB Archetypes'!$D$14)^2+(J13-'MLB Archetypes'!$E$14)^2+(K13-'MLB Archetypes'!$F$14)^2) -> 4.5825757 | AY13: =SQRT((H13-'MLB Archetypes'!$C$15)^2+(I13-'MLB Archetypes'!$D$15)^2+(J13-'MLB Archetypes'!$E$15)^2+(K13-'MLB Archetypes'!$F$15)^2) -> 4.472136 | AZ13: =SQRT((H13-'MLB Archetypes'!$C$16)^2+(I13-'MLB Archetypes'!$D$16)^2+(J13-'MLB Archetypes'!$E$16)^2+(K13-'MLB Archetypes'!$F$16)^2) -> 6 | BA13: =SQRT((H13-'MLB Archetypes'!$C$17)^2+(I13-'MLB Archetypes'!$D$17)^2+(J13-'MLB Archetypes'!$E$17)^2+(K13-'MLB Archetypes'!$F$17)^2) -> 4.6904158 | BB13: =SQRT((H13-'MLB Archetypes'!$C$18)^2+(I13-'MLB Archetypes'!$D$18)^2+(J13-'MLB Archetypes'!$E$18)^2+(K13-'MLB Archetypes'!$F$18)^2) -> 4.5825757 | BC13: =SQRT((H13-'MLB Archetypes'!$C$19)^2+(I13-'MLB Archetypes'!$D$19)^2+(J13-'MLB Archetypes'!$E$19)^2+(K13-'MLB Archetypes'!$F$19)^2) -> 5.0990195 | BD13: =INDEX('MLB Archetypes'!$B$2:$B$19,MATCH(MIN(AL13:BC13),AL13:BC13,0)) -> Jackie Robinson | BE13: =ROUND(10-MIN(AL13:BC13)/1.8,1) -> 7.5
... A73: Mii | B73: N/A | C73: Mii | D73: No | E73: No | F73: Right | G73: Right | H73: 6 | I73: 6 | J73: 6 | K73: 6 | L73: =H73+I73+J73+K73 -> 24 | M73: =ROUND(0.75*I73+0.25*K73,2) -> 6 | N73: =ROUND(0.7*J73+0.3*K73,2) -> 6 | O73: =ROUND((H73+J73+K73)/3,2) -> 6 | P73: =ROUND(0.85*H73+0.15*J73,2) -> 6 | Q73: =ROUND(0.6*J73+0.3*I73+0.1*H73,2) -> 6 | R73: =ROUND(0.7*I73+0.2*J73+0.1*K73,2) -> 6 | S73: =ROUND(0.13*I73+0.35*J73+0.52*K73,2) -> 6 | T73: =ROUND(0.4*I73+0.5*J73+0.1*K73,2) -> 6 | U73: =ROUND(0.1*I73+0.55*J73+0.35*K73,2) -> 6 | V73: =ROUND(0.6*I73+0.1*J73+0.3*K73,2) -> 6 | W73: =ROUND(0.15*I73+0.3*J73+0.55*K73,2) -> 6 | X73: =ROUND(0.46*I73+0.46*J73+0.08*K73,2) -> 6 | Y73: =IF(H73=MAX(H73:K73),"Pitcher (arm-first)",IF(I73=MAX(H73:K73),"Bat-first (corner/1B/DH)",IF(J73=MAX(H73:K73),"Defense-first (up-the-middle)","Speed-first (CF/leadoff)"))) -> Pitcher (arm-first) | Z73: =P73 -> 6 | AA73: =IF(F73="Right",Q73,-1) -> 6 | AB73: =R73 -> 6 | AC73: =IF(F73="Right",S73,-1) -> 6 | AD73: =IF(F73="Right",T73,-1) -> 6 | AE73: =IF(F73="Right",U73,-1) -> 6 | AF73: =V73 -> 6 | AG73: =W73 -> 6 | AH73: =X73 -> 6 | AI73: =INDEX($Z$1:$AH$1,MATCH(MAX(Z73:AH73),Z73:AH73,0)) -> P | AJ73: =MAX(Z73:AH73) -> 6 | AK73: =SUMPRODUCT(($AI$2:$AI$73=AI73)*($AJ$2:$AJ$73>AJ73))+SUMPRODUCT(($AI$2:$AI$73=AI73)*($AJ$2:$AJ$73=AJ73)*(ROW($AI$2:$AI$73)<ROW(AI73)))+1 -> 13 | AL73: =SQRT((H73-'MLB Archetypes'!$C$2)^2+(I73-'MLB Archetypes'!$D$2)^2+(J73-'MLB Archetypes'!$E$2)^2+(K73-'MLB Archetypes'!$F$2)^2) -> 6.4807407 | AM73: =SQRT((H73-'MLB Archetypes'!$C$3)^2+(I73-'MLB Archetypes'!$D$3)^2+(J73-'MLB Archetypes'!$E$3)^2+(K73-'MLB Archetypes'!$F$3)^2) -> 5.1961524 | AN73: =SQRT((H73-'MLB Archetypes'!$C$4)^2+(I73-'MLB Archetypes'!$D$4)^2+(J73-'MLB Archetypes'!$E$4)^2+(K73-'MLB Archetypes'!$F$4)^2) -> 5.9160798 | AO73: =SQRT((H73-'MLB Archetypes'!$C$5)^2+(I73-'MLB Archetypes'!$D$5)^2+(J73-'MLB Archetypes'!$E$5)^2+(K73-'MLB Archetypes'!$F$5)^2) -> 4.8989795 | AP73: =SQRT((H73-'MLB Archetypes'!$C$6)^2+(I73-'MLB Archetypes'!$D$6)^2+(J73-'MLB Archetypes'!$E$6)^2+(K73-'MLB Archetypes'!$F$6)^2) -> 5.8309519 | AQ73: =SQRT((H73-'MLB Archetypes'!$C$7)^2+(I73-'MLB Archetypes'!$D$7)^2+(J73-'MLB Archetypes'!$E$7)^2+(K73-'MLB Archetypes'!$F$7)^2) -> 5.3851648 | AR73: =SQRT((H73-'MLB Archetypes'!$C$8)^2+(I73-'MLB Archetypes'!$D$8)^2+(J73-'MLB Archetypes'!$E$8)^2+(K73-'MLB Archetypes'!$F$8)^2) -> 4.5825757 | AS73: =SQRT((H73-'MLB Archetypes'!$C$9)^2+(I73-'MLB Archetypes'!$D$9)^2+(J73-'MLB Archetypes'!$E$9)^2+(K73-'MLB Archetypes'!$F$9)^2) -> 4.5825757 | AT73: =SQRT((H73-'MLB Archetypes'!$C$10)^2+(I73-'MLB Archetypes'!$D$10)^2+(J73-'MLB Archetypes'!$E$10)^2+(K73-'MLB Archetypes'!$F$10)^2) -> 5.2915026 | AU73: =SQRT((H73-'MLB Archetypes'!$C$11)^2+(I73-'MLB Archetypes'!$D$11)^2+(J73-'MLB Archetypes'!$E$11)^2+(K73-'MLB Archetypes'!$F$11)^2) -> 5.3851648 | AV73: =SQRT((H73-'MLB Archetypes'!$C$12)^2+(I73-'MLB Archetypes'!$D$12)^2+(J73-'MLB Archetypes'!$E$12)^2+(K73-'MLB Archetypes'!$F$12)^2) -> 6.4807407 | AW73: =SQRT((H73-'MLB Archetypes'!$C$13)^2+(I73-'MLB Archetypes'!$D$13)^2+(J73-'MLB Archetypes'!$E$13)^2+(K73-'MLB Archetypes'!$F$13)^2) -> 5.1961524 | AX73: =SQRT((H73-'MLB Archetypes'!$C$14)^2+(I73-'MLB Archetypes'!$D$14)^2+(J73-'MLB Archetypes'!$E$14)^2+(K73-'MLB Archetypes'!$F$14)^2) -> 5.0990195 | AY73: =SQRT((H73-'MLB Archetypes'!$C$15)^2+(I73-'MLB Archetypes'!$D$15)^2+(J73-'MLB Archetypes'!$E$15)^2+(K73-'MLB Archetypes'!$F$15)^2) -> 5.7445626 | AZ73: =SQRT((H73-'MLB Archetypes'!$C$16)^2+(I73-'MLB Archetypes'!$D$16)^2+(J73-'MLB Archetypes'!$E$16)^2+(K73-'MLB Archetypes'!$F$16)^2) -> 5.7445626 | BA73: =SQRT((H73-'MLB Archetypes'!$C$17)^2+(I73-'MLB Archetypes'!$D$17)^2+(J73-'MLB Archetypes'!$E$17)^2+(K73-'MLB Archetypes'!$F$17)^2) -> 5.1961524 | BB73: =SQRT((H73-'MLB Archetypes'!$C$18)^2+(I73-'MLB Archetypes'!$D$18)^2+(J73-'MLB Archetypes'!$E$18)^2+(K73-'MLB Archetypes'!$F$18)^2) -> 5.0990195 | BC73: =SQRT((H73-'MLB Archetypes'!$C$19)^2+(I73-'MLB Archetypes'!$D$19)^2+(J73-'MLB Archetypes'!$E$19)^2+(K73-'MLB Archetypes'!$F$19)^2) -> 4.5825757 | BD73: =INDEX('MLB Archetypes'!$B$2:$B$19,MATCH(MIN(AL73:BC73),AL73:BC73,0)) -> Jackie Robinson | BE73: =ROUND(10-MIN(AL73:BC73)/1.8,1) -> 7.5

Sheet MLB Archetypes
A1: Position | B1: MLB Player Comp | C1: Pitch (illustrative) | D1: Bat (illustrative) | E1: Field (illustrative) | F1: Run (illustrative) | G1: Why this comp
A2: P | B2: Nolan Ryan | C2: 10 | D2: 2 | E2: 5 | F2: 3 | G2: Overpowering fastball arm; the archetype pure power pitcher.
A3: P | B3: Greg Maddux | C3: 9 | D3: 3 | E3: 6 | F3: 3 | G3: Command and guile over velocity; wins with control and fielding his position.
A4: C | B4: Johnny Bench | C4: 2 | D4: 7 | E4: 9 | F4: 3 | G4: Rare catcher who hit for real power and still ran the position defensively.
A5: C | B5: Ivan Rodriguez | C5: 2 | D5: 6 | E5: 8 | F5: 4 | G5: Plus arm and athleticism behind the plate with a genuinely useful bat.
A6: 1B | B6: Albert Pujols | C6: 2 | D6: 9 | E6: 6 | F6: 3 | G6: Middle-of-the-order slugger with enough glove not to be a liability.
A7: 1B | B7: Keith Hernandez | C7: 2 | D7: 6 | E7: 9 | F7: 4 | G7: Defined the position defensively; a slick glove first, power second.
A8: 2B | B8: Jackie Robinson | C8: 2 | D8: 6 | E8: 7 | F8: 8 | G8: Contact, instincts, and speed at the keystone over raw power.
A9: 2B | B9: Roberto Alomar | C9: 2 | D9: 7 | E9: 8 | F9: 6 | G9: A more power-and-glove all-around second baseman than a pure burner.
A10: 3B | B10: Mike Schmidt | C10: 2 | D10: 8 | E10: 8 | F10: 4 | G10: Power and Gold Glove defense at the hot corner together.
A11: 3B | B11: George Brett | C11: 2 | D11: 9 | E11: 6 | F11: 4 | G11: A bat-first third baseman who could still handle the position.
A12: SS | B12: Ozzie Smith | C12: 2 | D12: 3 | E12: 10 | F12: 7 | G12: Defense-first shortstop who won games with the glove, not the bat.
A13: SS | B13: Cal Ripken Jr. | C13: 2 | D13: 7 | E13: 7 | F13: 3 | G13: Redefined the position as a big, powerful hitter who could still play plus defense.
... A19: RF | B19: Roberto Clemente | C19: 2 | D19: 7 | E19: 8 | F19: 6 | G19: Defined by a cannon arm and all-around defense as much as the bat.

Sheet Position Leaderboard
A1: Optimal-Position Leaderboard (Top 5 per position, model-based)
A3: Position | B3: Rank 1 | C3: Score | D3: Rank 2 | E3: Score | F3: Rank 3 | G3: Score | H3: Rank 4 | I3: Score | J3: Rank 5 | K3: Score
A4: P | B4: =IFERROR(INDEX('Roster Data'!$A$2:$A$73,SUMPRODUCT(('Roster Data'!$AI$2:$AI$73=$A4)*('Roster Data'!$AK$2:$AK$73=1)*ROW('Roster Data'!$AI$2:$AI$73))-2+1),"—") -> Peach | C4: =IFERROR(INDEX('Roster Data'!$AJ$2:$AJ$73,SUMPRODUCT(('Roster Data'!$AI$2:$AI$73=$A4)*('Roster Data'!$AK$2:$AK$73=1)*ROW('Roster Data'!$AI$2:$AI$73))-2+1),"") -> 8.85 | D4: =IFERROR(INDEX('Roster Data'!$A$2:$A$73,SUMPRODUCT(('Roster Data'!$AI$2:$AI$73=$A4)*('Roster Data'!$AK$2:$AK$73=2)*ROW('Roster Data'!$AI$2:$AI$73))-2+1),"—") -> Boo | E4: =IFERROR(INDEX('Roster Data'!$AJ$2:$AJ$73,SUMPRODUCT(('Roster Data'!$AI$2:$AI$73=$A4)*('Roster Data'!$AK$2:$AK$73=2)*ROW('Roster Data'!$AI$2:$AI$73))-2+1),"") -> 8.1 | F4: =IFERROR(INDEX('Roster Data'!$A$2:$A$73,SUMPRODUCT(('Roster Data'!$AI$2:$AI$73=$A4)*('Roster Data'!$AK$2:$AK$73=3)*ROW('Roster Data'!$AI$2:$AI$73))-2+1),"—") -> Waluigi | G4: =IFERROR(INDEX('Roster Data'!$AJ$2:$AJ$73,SUMPRODUCT(('Roster Data'!$AI$2:$AI$73=$A4)*('Roster Data'!$AK$2:$AK$73=3)*ROW('Roster Data'!$AI$2:$AI$73))-2+1),"") -> 8 | H4: =IFERROR(INDEX('Roster Data'!$A$2:$A$73,SUMPRODUCT(('Roster Data'!$AI$2:$AI$73=$A4)*('Roster Data'!$AK$2:$AK$73=4)*ROW('Roster Data'!$AI$2:$AI$73))-2+1),"—") -> Magikoopa | I4: =IFERROR(INDEX('Roster Data'!$AJ$2:$AJ$73,SUMPRODUCT(('Roster Data'!$AI$2:$AI$73=$A4)*('Roster Data'!$AK$2:$AK$73=4)*ROW('Roster Data'!$AI$2:$AI$73))-2+1),"") -> 8 | J4: =IFERROR(INDEX('Roster Data'!$A$2:$A$73,SUMPRODUCT(('Roster Data'!$AI$2:$AI$73=$A4)*('Roster Data'!$AK$2:$AK$73=5)*ROW('Roster Data'!$AI$2:$AI$73))-2+1),"—") -> Red Magikoopa | K4: =IFERROR(INDEX('Roster Data'!$AJ$2:$AJ$73,SUMPRODUCT(('Roster Data'!$AI$2:$AI$73=$A4)*('Roster Data'!$AK$2:$AK$73=5)*ROW('Roster Data'!$AI$2:$AI$73))-2+1),"") -> 8
